Workbook

Sheet config
A2: date d'entrée | B2: 46023 | E2: Matricule | F2: Nom | G2: Prénom | H2: Anniversaire | I2: Dernières visites médicale | J2: Prochaines visites médicale | K2: R.482 A (1) | L2: R.482 B1 (2) | M2: R.482 C2 (3) | N2: R.482 C1 (4) | O2: R.482 5 | P2: R.482 D (7) | Q2: R.482 E (8) | R2: R.482 F (9) | S2: R.482 G (10) | T2: Tondeuse FI | U2: Grue R.490 | V2: B (Nacelle) | W2: Chariot R.489 / 3 | X2: Tronço | Y2: Permis BE - REMORQUE | Z2: Permis PL | AA2: Permis CE Sup Lourd | AB2: FIMO | AC2: AIPR | AD2: Premiers secours
E3: N019002 | F3: DEBREYNE | G3: Audrey
B4: début | C4: fin | E4: N024050 | F4: LUTARD | G4: Karyne
A5: Janvier | B5: =B2 -> 46023 | C5: =EOMONTH(B5,0) -> 46053 | E5: N018905 | F5: HAUTDECOEUR | G5: Laurence
A6: Février | B6: =EDATE(B5,1) -> 46054 | C6: =EOMONTH(B6,0) -> 46081 | E6: N016820 | F6: GRENET | G6: Eric
A7: Mars | B7: =EDATE(B6,1) -> 46082 | C7: =EOMONTH(B7,0) -> 46112 | E7: C003285 | F7: FOURCADE | G7: Hervé | I7: 45413 | J7: 46143
A8: Avril | B8: =EDATE(B7,1) -> 46113 | C8: =EOMONTH(B8,0) -> 46142 | E8: JT030845 | F8: GONCALVES | G8: Lionel | H8: 30758 | I8: 45627 | J8: 46357
A9: Mai | B9: =EDATE(B8,1) -> 46143 | C9: =EOMONTH(B9,0) -> 46173 | E9: N011045 | F9: SIGALA | G9: Jean-Christohpe | I9: 45413 | J9: 46143
A10: Juin | B10: =EDATE(B9,1) -> 46174 | C10: =EOMONTH(B10,0) -> 46203 | E10: N010036 | F10: BETTINGER | G10: Philippe
A11: Juillet | B11: =EDATE(B10,1) -> 46204 | C11: =EOMONTH(B11,0) -> 46234 | E11: N015967 | F11: TUCOULET | G11: Dorian | I11: 45383 | J11: 46113 | K11: 47178 | N11: 47178
A12: Août | B12: =EDATE(B11,1) -> 46235 | C12: =EOMONTH(B12,0) -> 46265 | E12: N017539 | F12: VRBOVSKA | G12: Xavier
A13: Septembre | B13: =EDATE(B12,1) -> 46266 | C13: =EOMONTH(B13,0) -> 46295 | E13: MAINTENANCE
A14: Octobre | B14: =EDATE(B13,1) -> 46296 | C14: =EOMONTH(B14,0) -> 46326 | E14: SURVEILLANT DE TRAVAUX
A15: Novembre | B15: =EDATE(B14,1) -> 46327 | C15: =EOMONTH(B15,0) -> 46356 | E15: C004587 | F15: BOURGOIN | G15: Jean-Baptiste
A16: Décembre | B16: =EDATE(B15,1) -> 46357 | C16: =EOMONTH(B16,0) -> 46387 | E16: N02645 | F16: MERCADIEU | G16: Baptiste
A17: Janvier | B17: =EDATE(B16,1) -> 46388 | C17: =EOMONTH(B17,0) -> 46418 | E17: ASDP
A18: Février | B18: =EDATE(B17,1) -> 46419 | C18: =EOMONTH(B18,0) -> 46446 | E18: C004845 | F18: GARCIA | G18: Yoan
E19: C005015 | F19: LARROUDE | G19: Christophe
E20: N020065 | F20: SAMITIER | G20: Beatrice
E21: C005216 | F21: PIEL | G21: Frédy
E22: PROPRETE
E23: JN020502 | F23: GOURVIAT | G23: Annabelle
E24: JT032516 | F24: LARTIGUE | G24: Laura
E25: JN010897 | F25: TRIQUENEAUX | G25: Benoit
E26: JN010381 | F26: ESPERON | G26: Alain
E27: JN010750 | F27: ROUGLAN | G27: William
E28: JN010461 | F28: NOURRI | G28: Danny
E29: REGIE
E30: AGENTS VOIRIE
E31: JT028103 | F31: BERRIO-GAUDNER | G31: Jacques
E32: C002908 | F32: FONTENEAU | G32: Fabrice | I32: 45536 | J32: 46266 | K32: 11780 | N32: 11232 | W32: 46661 | X32: X | Y32: X | Z32: 46447 | AC32: 46478
E33: C004504 | F33: GUIJARRO | G33: Juan-Pédro | I33: 45413 | J33: 46143 | K33: 46905 | N33: 12663 | Q33: 46722 | R33: 12663 | U33: 11018 | X33: X | Y33: X | Z33: 46082 | AA33: 46082 | AB33: 46813 | AC33: 46419
E34: T028198 | F34: GOUREAU | G34: Jonathan | I34: 45383 | J34: 46113 | X34: x
E35: C002986 | F35: LABORIE | G35: Jean-Louis | I35: 45778 | J35: 46508 | K35: 47209 | N35: 47209 | R35: 47209 | X35: X | Y35: X | Z35: 10959 | AA35: 10959
E36: C007317 | F36: LARRIEU | G36: Cédric | I36: 45383 | J36: 46113
E37: C004309 | F37: LEVIGNAT | G37: Didier
E38: C005624 | F38: MARTIN-HERNANDEZ | G38: Pierre | I38: 44927 | J38: 45658 | N38: 12086 | R38: 45931 | X38: X
E39: C007758 | F39: PIERRE | G39: Frantzy | I39: 45778 | J39: 46508 | K39: 47150 | N39: 47150 | R39: 11049 | X39: X | AC39: 11110
E40: C004609 | F40: SOLA | G40: Xavier | I40: 45383 | J40: 46113 | K40: 47119 | R40: 11018 | X40: X
E41: T029734 | F41: WEISS | G41: Miguel
...

Sheet Janvier 2026
A1: =config!B5 -> 46023
A2: =config!C5 -> 46053
P4: =A1 -> 46023 | Q4: =P4+1 -> 46024 | R4: =Q4+1 -> 46025 | S4: =R4+1 -> 46026 | T4: =S4+1 -> 46027 | U4: =T4+1 -> 46028 | V4: =U4+1 -> 46029 | W4: =V4+1 -> 46030 | X4: =W4+1 -> 46031 | ... AT4: =AS4+1 -> 46053
A5: =TEXT(A1,"mmmmmmmmmmmm") -> janvier
D8: TOTAL | P8: FERIE | AM8: ARRET EVP JAN
D9: P | E9: PC | F9: F | G9: AST | H9: CA | I9: RTT | J9: CEX | K9: R | L9: M | M9: AT | N9: TAD | O9: TP | P9: =IFERROR(WEEKDAY(P4),"") -> 5 | Q9: =IFERROR(WEEKDAY(Q4),"") -> 6 | R9: =IFERROR(WEEKDAY(R4),"") -> 7 | S9: =IFERROR(WEEKDAY(S4),"") -> 1 | T9: =IFERROR(WEEKDAY(T4),"") -> 2 | U9: =IFERROR(WEEKDAY(U4),"") -> 3 | V9: =IFERROR(WEEKDAY(V4),"") -> 4 | W9: =IFERROR(WEEKDAY(W4),"") -> 5 | ... AT9: =IFERROR(WEEKDAY(AT4),"") -> 7
A10: Matricule | B10: Nom | C10: Prénom | D10: PRESENCE | E10: PREV CONGES | F10: FORMATION | G10: ASTREINT | H10: CONGES ANNUEL | I10: RTT | J10: CONGES EXC | K10: RESERVE | L10: MALADIE | M10: ACCIDENT DE TRAVAIL | N10: TRAVAI A DISTANCE | O10: Tps partiel TH | P10: =DAY(P4) -> 1 | Q10: =DAY(Q4) -> 2 | R10: =DAY(R4) -> 3 | S10: =DAY(S4) -> 4 | T10: =DAY(T4) -> 5 | U10: =DAY(U4) -> 6 | V10: =DAY(V4) -> 7 | W10: =DAY(W4) -> 8 | ... AT10: =DAY(AT4) -> 31
A11: =IFERROR(IF(config!E3="","",config!E3),"") -> N019002 | B11: =IFERROR(IF(config!F3="","",config!F3),"") -> DEBREYNE | C11: =IFERROR(IF(config!G3="","",config!G3),"") -> Audrey | D11: =COUNTIF(P11:AS11,"p") -> 0 | E11: =COUNTIF(P11:AS11,"PC") -> 12 | F11: =COUNTIF(P11:AS11,"f") -> 0 | G11: =COUNTIF(P11:AS11,"ast") -> 0 | H11: =COUNTIF(P11:AS11,"cA") -> 0 | I11: =COUNTIF(P11:AS11,"rtt") -> 0 | J11: =COUNTIF(P11:AS11,"cex") -> 0 | K11: =COUNTIF(P11:AS11,"res") -> 0 | L11: =COUNTIF(P11:AS11,"mA") -> 0 | M11: =COUNTIF(P11:AS11,"at") -> 0 | N11: =COUNTIF(P11:AS11,"TAD") -> 0 | O11: =COUNTIF(P11:AS11,"TP") -> 0 | Q11: PC | X11: PC | AA11: PC | AB11: PC | AC11: PC | AD11: PC | AE11: PC | AH11: PC | AI11: PC | AJ11: PC | AK11: PC | AL11: PC | AV11: BUREAU
A12: =IFERROR(IF(config!E4="","",config!E4),"") -> N024050 | B12: =IFERROR(IF(config!F4="","",config!F4),"") -> LUTARD | C12: =IFERROR(IF(config!G4="","",config!G4),"") -> Karyne | D12: =COUNTIF(P12:AS12,"p") -> 0 | E12: =COUNTIF(P12:AS12,"PC") -> 1 | F12: =COUNTIF(P12:AS12,"f") -> 0 | G12: =COUNTIF(P12:AS12,"ast") -> 0 | H12: =COUNTIF(P12:AS12,"cA") -> 0 | I12: =COUNTIF(P12:AS12,"rtt") -> 0 | J12: =COUNTIF(P12:AS12,"cex") -> 0 | K12: =COUNTIF(P12:AS12,"res") -> 0 | L12: =COUNTIF(P12:AS12,"mA") -> 0 | M12: =COUNTIF(P12:AS12,"at") -> 0 | N12: =COUNTIF(P12:AS12,"TAD") -> 0 | O12: =COUNTIF(P12:AS12,"TP") -> 0 | Q12: PC | AV12: P | AW12: PC | AX12: F | AY12: AST | AZ12: CA | BA12: RTT | BB12: CEX | BC12: R | BD12: M | BE12: AT | BF12: TP
A13: =IFERROR(IF(config!E5="","",config!E5),"") -> N018905 | B13: =IFERROR(IF(config!F5="","",config!F5),"") -> HAUTDECOEUR | C13: =IFERROR(IF(config!G5="","",config!G5),"") -> Laurence | D13: =COUNTIF(P13:AS13,"p") -> 0 | E13: =COUNTIF(P13:AS13,"PC") -> 0 | F13: =COUNTIF(P13:AS13,"f") -> 0 | G13: =COUNTIF(P13:AS13,"ast") -> 0 | H13: =COUNTIF(P13:AS13,"cA") -> 0 | I13: =COUNTIF(P13:AS13,"rtt") -> 0 | J13: =COUNTIF(P13:AS13,"cex") -> 0 | K13: =COUNTIF(P13:AS13,"res") -> 0 | L13: =COUNTIF(P13:AS13,"mA") -> 0 | M13: =COUNTIF(P13:AS13,"at") -> 0 | N13: =COUNTIF(P13:AS13,"TAD") -> 0 | O13: =COUNTIF(P13:AS13,"TP") -> 0 | AV13: =COUNTIF(P11:AS29,"p") -> 0 | AW13: =COUNTIF(P11:AS29,"PC") -> 35 | AX13: =COUNTIF(P11:AS29,"f") -> 6 | AY13: =COUNTIF(P11:AS29,"ast") -> 0 | AZ13: =COUNTIF(P11:AS29,"ca") -> 0 | BA13: =COUNTIF(P11:AS29,"rtt") -> 0 | BB13: =COUNTIF(P11:AS29,"CEX") -> 21 | BC13: =COUNTIF(P11:AS29,"RES") -> 0 | BD13: =COUNTIF(P11:AS29,"MA") -> 0 | BE13: =COUNTIF(P11:AS29,"AT") -> 0 | BF13: =COUNTIF(P11:AS29,"TP") -> 0
A14: =IFERROR(IF(config!E6="","",config!E6),"") -> N016820 | B14: =IFERROR(IF(config!F6="","",config!F6),"") -> GRENET | C14: =IFERROR(IF(config!G6="","",config!G6),"") -> Eric | D14: =COUNTIF(P14:AS14,"p") -> 0 | E14: =COUNTIF(P14:AS14,"PC") -> 6 | F14: =COUNTIF(P14:AS14,"f") -> 0 | G14: =COUNTIF(P14:AS14,"ast") -> 0 | H14: =COUNTIF(P14:AS14,"cA") -> 0 | I14: =COUNTIF(P14:AS14,"rtt") -> 0 | J14: =COUNTIF(P14:AS14,"cex") -> 0 | K14: =COUNTIF(P14:AS14,"res") -> 0 | L14: =COUNTIF(P14:AS14,"mA") -> 0 | M14: =COUNTIF(P14:AS14,"at") -> 0 | N14: =COUNTIF(P14:AS14,"TAD") -> 0 | O14: =COUNTIF(P14:AS14,"TP") -> 0 | Q14: PC | AO14: PC | AP14: PC | AQ14: PC | AR14: PC | AS14: PC
A15: =IFERROR(IF(config!E7="","",config!E7),"") -> C003285 | B15: =IFERROR(IF(config!F7="","",config!F7),"") -> FOURCADE | C15: =IFERROR(IF(config!G7="","",config!G7),"") -> Hervé | D15: =COUNTIF(P15:AS15,"p") -> 0 | E15: =COUNTIF(P15:AS15,"PC") -> 0 | F15: =COUNTIF(P15:AS15,"f") -> 0 | G15: =COUNTIF(P15:AS15,"ast") -> 0 | H15: =COUNTIF(P15:AS15,"cA") -> 0 | I15: =COUNTIF(P15:AS15,"rtt") -> 0 | J15: =COUNTIF(P15:AS15,"cex") -> 0 | K15: =COUNTIF(P15:AS15,"res") -> 0 | L15: =COUNTIF(P15:AS15,"mA") -> 0 | M15: =COUNTIF(P15:AS15,"at") -> 0 | N15: =COUNTIF(P15:AS15,"TAD") -> 0 | O15: =COUNTIF(P15:AS15,"TP") -> 0
A16: =IFERROR(IF(config!E8="","",config!E8),"") -> JT030845 | B16: =IFERROR(IF(config!F8="","",config!F8),"") -> GONCALVES | C16: =IFERROR(IF(config!G8="","",config!G8),"") -> Lionel | D16: =COUNTIF(P16:AS16,"p") -> 0 | E16: =COUNTIF(P16:AS16,"PC") -> 0 | F16: =COUNTIF(P16:AS16,"f") -> 0 | G16: =COUNTIF(P16:AS16,"ast") -> 0 | H16: =COUNTIF(P16:AS16,"cA") -> 0 | I16: =COUNTIF(P16:AS16,"rtt") -> 0 | J16: =COUNTIF(P16:AS16,"cex") -> 0 | K16: =COUNTIF(P16:AS16,"res") -> 0 | L16: =COUNTIF(P16:AS16,"mA") -> 0 | M16: =COUNTIF(P16:AS16,"at") -> 0 | N16: =COUNTIF(P16:AS16,"TAD") -> 0 | O16: =COUNTIF(P16:AS16,"TP") -> 0
A17: =IFERROR(IF(config!E9="","",config!E9),"") -> N011045 | B17: =IFERROR(IF(config!F9="","",config!F9),"") -> SIGALA | C17: =IFERROR(IF(config!G9="","",config!G9),"") -> Jean-Christohpe | D17: =COUNTIF(P17:AS17,"p") -> 0 | E17: =COUNTIF(P17:AS17,"PC") -> 0 | F17: =COUNTIF(P17:AS17,"f") -> 0 | G17: =COUNTIF(P17:AS17,"ast") -> 0 | H17: =COUNTIF(P17:AS17,"cA") -> 0 | I17: =COUNTIF(P17:AS17,"rtt") -> 0 | J17: =COUNTIF(P17:AS17,"cex") -> 0 | K17: =COUNTIF(P17:AS17,"res") -> 0 | L17: =COUNTIF(P17:AS17,"mA") -> 0 | M17: =COUNTIF(P17:AS17,"at") -> 0 | N17: =COUNTIF(P17:AS17,"TAD") -> 0 | O17: =COUNTIF(P17:AS17,"TP") -> 0
A18: =IFERROR(IF(config!E10="","",config!E10),"") -> N010036 | B18: =IFERROR(IF(config!F10="","",config!F10),"") -> BETTINGER | C18: =IFERROR(IF(config!G10="","",config!G10),"") -> Philippe | D18: =COUNTIF(P18:AS18,"p") -> 0 | E18: =COUNTIF(P18:AS18,"PC") -> 0 | F18: =COUNTIF(P18:AS18,"f") -> 0 | G18: =COUNTIF(P18:AS18,"ast") -> 0 | H18: =COUNTIF(P18:AS18,"cA") -> 0 | I18: =COUNTIF(P18:AS18,"rtt") -> 0 | J18: =COUNTIF(P18:AS18,"cex") -> 21 | K18: =COUNTIF(P18:AS18,"res") -> 0 | L18: =COUNTIF(P18:AS18,"mA") -> 0 | M18: =COUNTIF(P18:AS18,"at") -> 0 | N18: =COUNTIF(P18:AS18,"TAD") -> 0 | O18: =COUNTIF(P18:AS18,"TP") -> 0 | Q18: CEX | T18: CEX | U18: CEX | V18: CEX | W18: CEX | X18: CEX | AA18: CEX | AB18: CEX | AC18: CEX | AD18: CEX | AE18: CEX | AH18: CEX | AI18: CEX | AJ18: CEX | AK18: CEX | AL18: CEX | AO18: CEX | AP18: CEX | AQ18: CEX | AR18: CEX | AS18: CEX
A19: =IFERROR(IF(config!E11="","",config!E11),"") -> N015967 | B19: =IFERROR(IF(config!F11="","",config!F11),"") -> TUCOULET | C19: =IFERROR(IF(config!G11="","",config!G11),"") -> Dorian | D19: =COUNTIF(P19:AS19,"p") -> 0 | E19: =COUNTIF(P19:AS19,"PC") -> 6 | F19: =COUNTIF(P19:AS19,"f") -> 0 | G19: =COUNTIF(P19:AS19,"ast") -> 0 | H19: =COUNTIF(P19:AS19,"cA") -> 0 | I19: =COUNTIF(P19:AS19,"rtt") -> 0 | J19: =COUNTIF(P19:AS19,"cex") -> 0 | K19: =COUNTIF(P19:AS19,"res") -> 0 | L19: =COUNTIF(P19:AS19,"mA") -> 0 | M19: =COUNTIF(P19:AS19,"at") -> 0 | N19: =COUNTIF(P19:AS19,"TAD") -> 0 | O19: =COUNTIF(P19:AS19,"TP") -> 0 | Q19: PC | T19: PC | U19: PC | V19: PC | W19: PC | X19: PC
A20: =IFERROR(IF(config!E12="","",config!E12),"") -> N017539 | B20: =IFERROR(IF(config!F12="","",config!F12),"") -> VRBOVSKA | C20: =IFERROR(IF(config!G12="","",config!G12),"") -> Xavier | D20: =COUNTIF(P20:AS20,"p") -> 0 | E20: =COUNTIF(P20:AS20,"PC") -> 1 | F20: =COUNTIF(P20:AS20,"f") -> 6 | G20: =COUNTIF(P20:AS20,"ast") -> 0 | H20: =COUNTIF(P20:AS20,"cA") -> 0 | I20: =COUNTIF(P20:AS20,"rtt") -> 0 | J20: =COUNTIF(P20:AS20,"cex") -> 0 | K20: =COUNTIF(P20:AS20,"res") -> 0 | L20: =COUNTIF(P20:AS20,"mA") -> 0 | M20: =COUNTIF(P20:AS20,"at") -> 0 | N20: =COUNTIF(P20:AS20,"TAD") -> 0 | O20: =COUNTIF(P20:AS20,"TP") -> 0 | Q20: PC | AI20: F | AJ20: F | AK20: F | AQ20: F | AR20: F | AS20: F
A21: =IFERROR(IF(config!E13="","",config!E13),"") -> MAINTENANCE
A22: =IFERROR(IF(config!E14="","",config!E14),"") -> SURVEILLANT DE TRAVAUX
A23: =IFERROR(IF(config!E15="","",config!E15),"") -> C004587 | B23: =IFERROR(IF(config!F15="","",config!F15),"") -> BOURGOIN | C23: =IFERROR(IF(config!G15="","",config!G15),"") -> Jean-Baptiste | D23: =COUNTIF(P23:AS23,"p") -> 0 | E23: =COUNTIF(P23:AS23,"PC") -> 1 | F23: =COUNTIF(P23:AS23,"f") -> 0 | G23: =COUNTIF(P23:AS23,"ast") -> 0 | H23: =COUNTIF(P23:AS23,"cA") -> 0 | I23: =COUNTIF(P23:AS23,"rtt") -> 0 | J23: =COUNTIF(P23:AS23,"cex") -> 0 | K23: =COUNTIF(P23:AS23,"res") -> 0 | L23: =COUNTIF(P23:AS23,"mA") -> 0 | M23: =COUNTIF(P23:AS23,"at") -> 0 | N23: =COUNTIF(P23:AS23,"TAD") -> 0 | O23: =COUNTIF(P23:AS23,"TP") -> 0 | Q23: PC
A24: =IFERROR(IF(config!E16="","",config!E16),"") -> N02645 | B24: =IFERROR(IF(config!F16="","",config!F16),"") -> MERCADIEU | C24: =IFERROR(IF(config!G16="","",config!G16),"") -> Baptiste | D24: =COUNTIF(P24:AS24,"p") -> 0 | E24: =COUNTIF(P24:AS24,"PC") -> 1 | F24: =COUNTIF(P24:AS24,"f") -> 0 | G24: =COUNTIF(P24:AS24,"ast") -> 0 | H24: =COUNTIF(P24:AS24,"cA") -> 0 | I24: =COUNTIF(P24:AS24,"rtt") -> 0 | J24: =COUNTIF(P24:AS24,"cex") -> 0 | K24: =COUNTIF(P24:AS24,"res") -> 0 | L24: =COUNTIF(P24:AS24,"mA") -> 0 | M24: =COUNTIF(P24:AS24,"at") -> 0 | N24: =COUNTIF(P24:AS24,"TAD") -> 0 | O24: =COUNTIF(P24:AS24,"TP") -> 0 | Q24: PC
A25: =IFERROR(IF(config!E17="","",config!E17),"") -> ASDP
A26: =IFERROR(IF(config!E18="","",config!E18),"") -> C004845 | B26: =IFERROR(IF(config!F18="","",config!F18),"") -> GARCIA | C26: =IFERROR(IF(config!G18="","",config!G18),"") -> Yoan | D26: =COUNTIF(P26:AS26,"p") -> 0 | E26: =COUNTIF(P26:AS26,"PC") -> 0 | F26: =COUNTIF(P26:AS26,"f") -> 0 | G26: =COUNTIF(P26:AS26,"ast") -> 0 | H26: =COUNTIF(P26:AS26,"cA") -> 0 | I26: =COUNTIF(P26:AS26,"rtt") -> 0 | J26: =COUNTIF(P26:AS26,"cex") -> 0 | K26: =COUNTIF(P26:AS26,"res") -> 0 | L26: =COUNTIF(P26:AS26,"mA") -> 0 | M26: =COUNTIF(P26:AS26,"at") -> 0 | N26: =COUNTIF(P26:AS26,"TAD") -> 0 | O26: =COUNTIF(P26:AS26,"TP") -> 0
A27: =IFERROR(IF(config!E19="","",config!E19),"") -> C005015 | B27: =IFERROR(IF(config!F19="","",config!F19),"") -> LARROUDE | C27: =IFERROR(IF(config!G19="","",config!G19),"") -> Christophe | D27: =COUNTIF(P27:AS27,"p") -> 0 | E27: =COUNTIF(P27:AS27,"PC") -> 6 | F27: =COUNTIF(P27:AS27,"f") -> 0 | G27: =COUNTIF(P27:AS27,"ast") -> 0 | H27: =COUNTIF(P27:AS27,"cA") -> 0 | I27: =COUNTIF(P27:AS27,"rtt") -> 0 | J27: =COUNTIF(P27:AS27,"cex") -> 0 | K27: =COUNTIF(P27:AS27,"res") -> 0 | L27: =COUNTIF(P27:AS27,"mA") -> 0 | M27: =COUNTIF(P27:AS27,"at") -> 0 | N27: =COUNTIF(P27:AS27,"TAD") -> 0 | O27: =COUNTIF(P27:AS27,"TP") -> 0 | Q27: PC | T27: PC | U27: PC | V27: PC | W27: PC | X27: PC
A28: =IFERROR(IF(config!E20="","",config!E20),"") -> N020065 | B28: =IFERROR(IF(config!F20="","",config!F20),"") -> SAMITIER | C28: =IFERROR(IF(config!G20="","",config!G20),"") -> Beatrice | D28: =COUNTIF(P28:AS28,"p") -> 0 | E28: =COUNTIF(P28:AS28,"PC") -> 1 | F28: =COUNTIF(P28:AS28,"f") -> 0 | G28: =COUNTIF(P28:AS28,"ast") -> 0 | H28: =COUNTIF(P28:AS28,"cA") -> 0 | I28: =COUNTIF(P28:AS28,"rtt") -> 0 | J28: =COUNTIF(P28:AS28,"cex") -> 0 | K28: =COUNTIF(P28:AS28,"res") -> 0 | L28: =COUNTIF(P28:AS28,"mA") -> 0 | M28: =COUNTIF(P28:AS28,"at") -> 0 | N28: =COUNTIF(P28:AS28,"TAD") -> 0 | O28: =COUNTIF(P28:AS28,"TP") -> 0 | Q28: PC
A29: =IFERROR(IF(config!E21="","",config!E21),"") -> C005216 | B29: =IFERROR(IF(config!F21="","",config!F21),"") -> PIEL | C29: =IFERROR(IF(config!G21="","",config!G21),"") -> Frédy | D29: =COUNTIF(P29:AS29,"p") -> 0 | E29: =COUNTIF(P29:AS29,"PC") -> 0 | F29: =COUNTIF(P29:AS29,"f") -> 0 | G29: =COUNTIF(P29:AS29,"ast") -> 0 | H29: =COUNTIF(P29:AS29,"cA") -> 0 | I29: =COUNTIF(P29:AS29,"rtt") -> 0 | J29: =COUNTIF(P29:AS29,"cex") -> 0 | K29: =COUNTIF(P29:AS29,"res") -> 0 | L29: =COUNTIF(P29:AS29,"mA") -> 0 | M29: =COUNTIF(P29:AS29,"at") -> 0 | N29: =COUNTIF(P29:AS29,"TAD") -> 0 | O29: =COUNTIF(P29:AS29,"TP") -> 0
A30: =IFERROR(IF(config!E22="","",config!E22),"") -> PROPRETE
A31: =IFERROR(IF(config!E23="","",config!E23),"") -> JN020502 | B31: =IFERROR(IF(config!F23="","",config!F23),"") -> GOURVIAT | C31: =IFERROR(IF(config!G23="","",config!G23),"") -> Annabelle | D31: =COUNTIF(P31:AS31,"p") -> 0 | E31: =COUNTIF(P31:AS31,"PC") -> 0 | F31: =COUNTIF(P31:AS31,"f") -> 0 | G31: =COUNTIF(P31:AS31,"ast") -> 0 | H31: =COUNTIF(P31:AS31,"cA") -> 0 | I31: =COUNTIF(P31:AS31,"rtt") -> 0 | J31: =COUNTIF(P31:AS31,"cex") -> 0 | K31: =COUNTIF(P31:AS31,"res") -> 0 | L31: =COUNTIF(P31:AS31,"mA") -> 0 | M31: =COUNTIF(P31:AS31,"at") -> 0 | N31: =COUNTIF(P31:AS31,"TAD") -> 0 | O31: =COUNTIF(P31:AS31,"TP") -> 0
A32: =IFERROR(IF(config!E24="","",config!E24),"") -> JT032516 | B32: =IFERROR(IF(config!F24="","",config!F24),"") -> LARTIGUE | C32: =IFERROR(IF(config!G24="","",config!G24),"") -> Laura | D32: =COUNTIF(P32:AS32,"p") -> 0 | E32: =COUNTIF(P32:AS32,"PC") -> 0 | F32: =COUNTIF(P32:AS32,"f") -> 0 | G32: =COUNTIF(P32:AS32,"ast") -> 0 | H32: =COUNTIF(P32:AS32,"cA") -> 0 | I32: =COUNTIF(P32:AS32,"rtt") -> 0 | J32: =COUNTIF(P32:AS32,"cex") -> 0 | K32: =COUNTIF(P32:AS32,"res") -> 0 | L32: =COUNTIF(P32:AS32,"mA") -> 0 | M32: =COUNTIF(P32:AS32,"at") -> 0 | N32: =COUNTIF(P32:AS32,"TAD") -> 0 | O32: =COUNTIF(P32:AS32,"TP") -> 0
A33: =IFERROR(IF(config!E25="","",config!E25),"") -> JN010897 | B33: =IFERROR(IF(config!F25="","",config!F25),"") -> TRIQUENEAUX | C33: =IFERROR(IF(config!G25="","",config!G25),"") -> Benoit | D33: =COUNTIF(P33:AS33,"p") -> 0 | E33: =COUNTIF(P33:AS33,"PC") -> 0 | F33: =COUNTIF(P33:AS33,"f") -> 0 | G33: =COUNTIF(P33:AS33,"ast") -> 0 | H33: =COUNTIF(P33:AS33,"cA") -> 0 | I33: =COUNTIF(P33:AS33,"rtt") -> 0 | J33: =COUNTIF(P33:AS33,"cex") -> 0 | K33: =COUNTIF(P33:AS33,"res") -> 0 | L33: =COUNTIF(P33:AS33,"mA") -> 0 | M33: =COUNTIF(P33:AS33,"at") -> 0 | N33: =COUNTIF(P33:AS33,"TAD") -> 0 | O33: =COUNTIF(P33:AS33,"TP") -> 0
A34: =IFERROR(IF(config!E26="","",config!E26),"") -> JN010381 | B34: =IFERROR(IF(config!F26="","",config!F26),"") -> ESPERON | C34: =IFERROR(IF(config!G26="","",config!G26),"") -> Alain | D34: =COUNTIF(P34:AS34,"p") -> 0 | E34: =COUNTIF(P34:AS34,"PC") -> 0 | F34: =COUNTIF(P34:AS34,"f") -> 0 | G34: =COUNTIF(P34:AS34,"ast") -> 0 | H34: =COUNTIF(P34:AS34,"cA") -> 0 | I34: =COUNTIF(P34:AS34,"rtt") -> 0 | J34: =COUNTIF(P34:AS34,"cex") -> 0 | K34: =COUNTIF(P34:AS34,"res") -> 0 | L34: =COUNTIF(P34:AS34,"mA") -> 0 | M34: =COUNTIF(P34:AS34,"at") -> 0 | N34: =COUNTIF(P34:AS34,"TAD") -> 0 | O34: =COUNTIF(P34:AS34,"TP") -> 0
A35: =IFERROR(IF(config!E27="","",config!E27),"") -> JN010750 | B35: =IFERROR(IF(config!F27="","",config!F27),"") -> ROUGLAN | C35: =IFERROR(IF(config!G27="","",config!G27),"") -> William | D35: =COUNTIF(P35:AS35,"p") -> 0 | E35: =COUNTIF(P35:AS35,"PC") -> 0 | F35: =COUNTIF(P35:AS35,"f") -> 0 | G35: =COUNTIF(P35:AS35,"ast") -> 0 | H35: =COUNTIF(P35:AS35,"cA") -> 0 | I35: =COUNTIF(P35:AS35,"rtt") -> 0 | J35: =COUNTIF(P35:AS35,"cex") -> 0 | K35: =COUNTIF(P35:AS35,"res") -> 0 | L35: =COUNTIF(P35:AS35,"mA") -> 0 | M35: =COUNTIF(P35:AS35,"at") -> 0 | N35: =COUNTIF(P35:AS35,"TAD") -> 0 | O35: =COUNTIF(P35:AS35,"TP") -> 0
A36: =IFERROR(IF(config!E28="","",config!E28),"") -> JN010461 | B36: =IFERROR(IF(config!F28="","",config!F28),"") -> NOURRI | C36: =IFERROR(IF(config!G28="","",config!G28),"") -> Danny | D36: =COUNTIF(P36:AS36,"p") -> 0 | E36: =COUNTIF(P36:AS36,"PC") -> 0 | F36: =COUNTIF(P36:AS36,"f") -> 0 | G36: =COUNTIF(P36:AS36,"ast") -> 0 | H36: =COUNTIF(P36:AS36,"cA") -> 0 | I36: =COUNTIF(P36:AS36,"rtt") -> 0 | J36: =COUNTIF(P36:AS36,"cex") -> 0 | K36: =COUNTIF(P36:AS36,"res") -> 0 | L36: =COUNTIF(P36:AS36,"mA") -> 0 | M36: =COUNTIF(P36:AS36,"at") -> 0 | N36: =COUNTIF(P36:AS36,"TAD") -> 0 | O36: =COUNTIF(P36:AS36,"TP") -> 0
A37: =IFERROR(IF(config!E29="","",config!E29),"") -> REGIE
A38: =IFERROR(IF(config!E30="","",config!E30),"") -> AGENTS VOIRIE | AV38: VOIRIE
A39: =IFERROR(IF(config!E31="","",config!E31),"") -> JT028103 | B39: =IFERROR(IF(config!F31="","",config!F31),"") -> BERRIO-GAUDNER | C39: =IFERROR(IF(config!G31="","",config!G31),"") -> Jacques | D39: =COUNTIF(P39:AS39,"p") -> 0 | E39: =COUNTIF(P39:AS39,"PC") -> 0 | F39: =COUNTIF(P39:AS39,"f") -> 0 | G39: =COUNTIF(P39:AS39,"ast") -> 0 | H39: =COUNTIF(P39:AS39,"cA") -> 0 | I39: =COUNTIF(P39:AS39,"rtt") -> 0 | J39: =COUNTIF(P39:AS39,"cex") -> 0 | K39: =COUNTIF(P39:AS39,"res") -> 0 | L39: =COUNTIF(P39:AS39,"mA") -> 0 | M39: =COUNTIF(P39:AS39,"at") -> 0 | N39: =COUNTIF(P39:AS39,"TAD") -> 0 | O39: =COUNTIF(P39:AS39,"TP") -> 0 | AV39: P | AW39: PC | AX39: F | AY39: AST | AZ39: CA | BA39: RTT | BB39: CEX | BC39: R | BD39: M | BE39: AT | BF39: TP
A40: =IFERROR(IF(config!E32="","",config!E32),"") -> C002908 | B40: =IFERROR(IF(config!F32="","",config!F32),"") -> FONTENEAU | C40: =IFERROR(IF(config!G32="","",config!G32),"") -> Fabrice | D40: =COUNTIF(P40:AS40,"p") -> 0 | E40: =COUNTIF(P40:AS40,"PC") -> 1 | F40: =COUNTIF(P40:AS40,"f") -> 0 | G40: =COUNTIF(P40:AS40,"ast") -> 0 | H40: =COUNTIF(P40:AS40,"cA") -> 0 | I40: =COUNTIF(P40:AS40,"rtt") -> 0 | J40: =COUNTIF(P40:AS40,"cex") -> 0 | K40: =COUNTIF(P40:AS40,"res") -> 0 | L40: =COUNTIF(P40:AS40,"mA") -> 0 | M40: =COUNTIF(P40:AS40,"at") -> 0 | N40: =COUNTIF(P40:AS40,"TAD") -> 0 | O40: =COUNTIF(P40:AS40,"TP") -> 0 | Q40: PC | AV40: =COUNTIF(P39:AS49,"p") -> 0 | AW40: =COUNTIF(P39:AS49,"pc") -> 2 | AX40: =COUNTIF(P39:AS49,"f") -> 0 | AY40: =COUNTIF(P39:AS49,"ast") -> 0 | AZ40: =COUNTIF(P39:AS49,"cA") -> 0 | BA40: =COUNTIF(P39:AS49,"rtt") -> 0 | BB40: =COUNTIF(P39:AS49,"cex") -> 0 | BC40: =COUNTIF(P39:AS49,"RES") -> 0 | BD40: =COUNTIF(P39:AS49,"MA") -> 0 | BE40: =COUNTIF(P39:AS49,"at") -> 30 | BF40: =COUNTIF(P39:AS49,"TP") -> 0
A41: =IFERROR(IF(config!E33="","",config!E33),"") -> C004504 | B41: =IFERROR(IF(config!F33="","",config!F33),"") -> GUIJARRO | C41: =IFERROR(IF(config!G33="","",config!G33),"") -> Juan-Pédro | D41: =COUNTIF(P41:AS41,"p") -> 0 | E41: =COUNTIF(P41:AS41,"PC") -> 1 | F41: =COUNTIF(P41:AS41,"f") -> 0 | G41: =COUNTIF(P41:AS41,"ast") -> 0 | H41: =COUNTIF(P41:AS41,"cA") -> 0 | I41: =COUNTIF(P41:AS41,"rtt") -> 0 | J41: =COUNTIF(P41:AS41,"cex") -> 0 | K41: =COUNTIF(P41:AS41,"res") -> 0 | L41: =COUNTIF(P41:AS41,"mA") -> 0 | M41: =COUNTIF(P41:AS41,"at") -> 0 | N41: =COUNTIF(P41:AS41,"TAD") -> 0 | O41: =COUNTIF(P41:AS41,"TP") -> 0 | Q41: PC
A42: =IFERROR(IF(config!E34="","",config!E34),"") -> T028198 | B42: =IFERROR(IF(config!F34="","",config!F34),"") -> GOUREAU | C42: =IFERROR(IF(config!G34="","",config!G34),"") -> Jonathan | D42: =COUNTIF(P42:AS42,"p") -> 0 | E42: =COUNTIF(P42:AS42,"PC") -> 0 | F42: =COUNTIF(P42:AS42,"f") -> 0 | G42: =COUNTIF(P42:AS42,"ast") -> 0 | H42: =COUNTIF(P42:AS42,"cA") -> 0 | I42: =COUNTIF(P42:AS42,"rtt") -> 0 | J42: =COUNTIF(P42:AS42,"cex") -> 0 | K42: =COUNTIF(P42:AS42,"res") -> 0 | L42: =COUNTIF(P42:AS42,"mA") -> 0 | M42: =COUNTIF(P42:AS42,"at") -> 0 | N42: =COUNTIF(P42:AS42,"TAD") -> 0 | O42: =COUNTIF(P42:AS42,"TP") -> 0
A43: =IFERROR(IF(config!E35="","",config!E35),"") -> C002986 | B43: =IFERROR(IF(config!F35="","",config!F35),"") -> LABORIE | C43: =IFERROR(IF(config!G35="","",config!G35),"") -> Jean-Louis | D43: =COUNTIF(P43:AS43,"p") -> 0 | E43: =COUNTIF(P43:AS43,"PC") -> 0 | F43: =COUNTIF(P43:AS43,"f") -> 0 | G43: =COUNTIF(P43:AS43,"ast") -> 0 | H43: =COUNTIF(P43:AS43,"cA") -> 0 | I43: =COUNTIF(P43:AS43,"rtt") -> 0 | J43: =COUNTIF(P43:AS43,"cex") -> 0 | K43: =COUNTIF(P43:AS43,"res") -> 0 | L43: =COUNTIF(P43:AS43,"mA") -> 0 | M43: =COUNTIF(P43:AS43,"at") -> 0 | N43: =COUNTIF(P43:AS43,"TAD") -> 0 | O43: =COUNTIF(P43:AS43,"TP") -> 0
...

Sheet Fevrier 2026
A1: =config!B6 -> 46054
A2: =config!C6 -> 46081
P4: =A1 -> 46054 | Q4: =P4+1 -> 46055 | R4: =Q4+1 -> 46056 | S4: =R4+1 -> 46057 | T4: =S4+1 -> 46058 | U4: =T4+1 -> 46059 | V4: =U4+1 -> 46060 | W4: =V4+1 -> 46061 | X4: =W4+1 -> 46062 | ... AQ4: =AP4+1 -> 46081
A5: =TEXT(A1,"mmmmmmmmmmmm") -> février
D8: TOTAL | AM8: ARRET EVP JAN
D9: P | E9: PC | F9: F | G9: AST | H9: CA | I9: RTT | J9: CEX | K9: R | L9: M | M9: AT | N9: TAD | O9: TP | P9: =IFERROR(WEEKDAY(P4),"") -> 1 | Q9: =IFERROR(WEEKDAY(Q4),"") -> 2 | R9: =IFERROR(WEEKDAY(R4),"") -> 3 | S9: =IFERROR(WEEKDAY(S4),"") -> 4 | T9: =IFERROR(WEEKDAY(T4),"") -> 5 | U9: =IFERROR(WEEKDAY(U4),"") -> 6 | V9: =IFERROR(WEEKDAY(V4),"") -> 7 | W9: =IFERROR(WEEKDAY(W4),"") -> 1 | ... AQ9: =IFERROR(WEEKDAY(AQ4),"") -> 7
A10: Matricule | B10: Nom | C10: Prénom | D10: PRESENCE | E10: PREV CONGES | F10: FORMATION | G10: ASTREINT | H10: CONGES ANNUEL | I10: RTT | J10: CONGES EXC | K10: RESERVE | L10: MALADIE | M10: ACCIDENT DE TRAVAIL | N10: TRAVAI A DISTANCE | O10: Tps partiel TH | P10: =DAY(P4) -> 1 | Q10: =DAY(Q4) -> 2 | R10: =DAY(R4) -> 3 | S10: =DAY(S4) -> 4 | T10: =DAY(T4) -> 5 | U10: =DAY(U4) -> 6 | V10: =DAY(V4) -> 7 | W10: =DAY(W4) -> 8 | ... AQ10: =DAY(AQ4) -> 28
A11: =IFERROR(IF(config!E3="","",config!E3),"") -> N019002 | B11: =IFERROR(IF(config!F3="","",config!F3),"") -> DEBREYNE | C11: =IFERROR(IF(config!G3="","",config!G3),"") -> Audrey | D11: =COUNTIF(P11:AQ11,"p") -> 0 | E11: =COUNTIF(P11:AQ11,"PC") -> 6 | F11: =COUNTIF(P11:AQ11,"f") -> 0 | G11: =COUNTIF(P11:AQ11,"ast") -> 0 | H11: =COUNTIF(P11:AQ11,"cA") -> 0 | I11: =COUNTIF(P11:AQ11,"rtt") -> 0 | J11: =COUNTIF(P11:AQ11,"cex") -> 0 | K11: =COUNTIF(P11:AQ11,"res") -> 0 | L11: =COUNTIF(P11:AQ11,"mA") -> 0 | M11: =COUNTIF(P11:AQ11,"at") -> 0 | N11: =COUNTIF(P11:AQ11,"TAD") -> 0 | O11: =COUNTIF(P11:AQ11,"TP") -> 0 | U11: PC | X11: PC | Y11: PC | Z11: PC | AA11: PC | AB11: PC | AS11: BUREAU
A12: =IFERROR(IF(config!E4="","",config!E4),"") -> N024050 | B12: =IFERROR(IF(config!F4="","",config!F4),"") -> LUTARD | C12: =IFERROR(IF(config!G4="","",config!G4),"") -> Karyne | D12: =COUNTIF(P12:AQ12,"p") -> 0 | E12: =COUNTIF(P12:AQ12,"PC") -> 1 | F12: =COUNTIF(P12:AQ12,"f") -> 0 | G12: =COUNTIF(P12:AQ12,"ast") -> 0 | H12: =COUNTIF(P12:AQ12,"cA") -> 0 | I12: =COUNTIF(P12:AQ12,"rtt") -> 0 | J12: =COUNTIF(P12:AQ12,"cex") -> 0 | K12: =COUNTIF(P12:AQ12,"res") -> 0 | L12: =COUNTIF(P12:AQ12,"mA") -> 0 | M12: =COUNTIF(P12:AQ12,"at") -> 0 | N12: =COUNTIF(P12:AQ12,"TAD") -> 0 | O12: =COUNTIF(P12:AQ12,"TP") -> 0 | R12: PC | AS12: P | AT12: PC | AU12: F | AV12: AST | AW12: CA | AX12: RTT | AY12: CEX | AZ12: R | BA12: M | BB12: AT | BC12: TP
A13: =IFERROR(IF(config!E5="","",config!E5),"") -> N018905 | B13: =IFERROR(IF(config!F5="","",config!F5),"") -> HAUTDECOEUR | C13: =IFERROR(IF(config!G5="","",config!G5),"") -> Laurence | D13: =COUNTIF(P13:AQ13,"p") -> 0 | E13: =COUNTIF(P13:AQ13,"PC") -> 0 | F13: =COUNTIF(P13:AQ13,"f") -> 0 | G13: =COUNTIF(P13:AQ13,"ast") -> 0 | H13: =COUNTIF(P13:AQ13,"cA") -> 0 | I13: =COUNTIF(P13:AQ13,"rtt") -> 0 | J13: =COUNTIF(P13:AQ13,"cex") -> 0 | K13: =COUNTIF(P13:AQ13,"res") -> 0 | L13: =COUNTIF(P13:AQ13,"mA") -> 0 | M13: =COUNTIF(P13:AQ13,"at") -> 0 | N13: =COUNTIF(P13:AQ13,"TAD") -> 0 | O13: =COUNTIF(P13:AQ13,"TP") -> 0 | AS13: =COUNTIF(P11:AQ29,"p") -> 0 | AT13: =COUNTIF(P11:AQ29,"PC") -> 18 | AU13: =COUNTIF(P11:AQ29,"f") -> 0 | AV13: =COUNTIF(P11:AQ29,"ast") -> 0 | AW13: =COUNTIF(P11:AQ29,"ca") -> 6 | AX13: =COUNTIF(P11:AQ29,"rtt") -> 2 | AY13: =COUNTIF(P11:AQ29,"CEX") -> 12 | AZ13: =COUNTIF(P11:AQ29,"RES") -> 0 | BA13: =COUNTIF(P11:AQ29,"MA") -> 0 | BB13: =COUNTIF(P11:AQ29,"AT") -> 0 | BC13: =COUNTIF(P11:AQ29,"TP") -> 0
A14: =IFERROR(IF(config!E6="","",config!E6),"") -> N016820 | B14: =IFERROR(IF(config!F6="","",config!F6),"") -> GRENET | C14: =IFERROR(IF(config!G6="","",config!G6),"") -> Eric | D14: =COUNTIF(P14:AQ14,"p") -> 0 | E14: =COUNTIF(P14:AQ14,"PC") -> 0 | F14: =COUNTIF(P14:AQ14,"f") -> 0 | G14: =COUNTIF(P14:AQ14,"ast") -> 0 | H14: =COUNTIF(P14:AQ14,"cA") -> 0 | I14: =COUNTIF(P14:AQ14,"rtt") -> 0 | J14: =COUNTIF(P14:AQ14,"cex") -> 0 | K14: =COUNTIF(P14:AQ14,"res") -> 0 | L14: =COUNTIF(P14:AQ14,"mA") -> 0 | M14: =COUNTIF(P14:AQ14,"at") -> 0 | N14: =COUNTIF(P14:AQ14,"TAD") -> 0 | O14: =COUNTIF(P14:AQ14,"TP") -> 0
A15: =IFERROR(IF(config!E7="","",config!E7),"") -> C003285 | B15: =IFERROR(IF(config!F7="","",config!F7),"") -> FOURCADE | C15: =IFERROR(IF(config!G7="","",config!G7),"") -> Hervé | D15: =COUNTIF(P15:AQ15,"p") -> 0 | E15: =COUNTIF(P15:AQ15,"PC") -> 0 | F15: =COUNTIF(P15:AQ15,"f") -> 0 | G15: =COUNTIF(P15:AQ15,"ast") -> 0 | H15: =COUNTIF(P15:AQ15,"cA") -> 0 | I15: =COUNTIF(P15:AQ15,"rtt") -> 0 | J15: =COUNTIF(P15:AQ15,"cex") -> 0 | K15: =COUNTIF(P15:AQ15,"res") -> 0 | L15: =COUNTIF(P15:AQ15,"mA") -> 0 | M15: =COUNTIF(P15:AQ15,"at") -> 0 | N15: =COUNTIF(P15:AQ15,"TAD") -> 0 | O15: =COUNTIF(P15:AQ15,"TP") -> 0
A16: =IFERROR(IF(config!E8="","",config!E8),"") -> JT030845 | B16: =IFERROR(IF(config!F8="","",config!F8),"") -> GONCALVES | C16: =IFERROR(IF(config!G8="","",config!G8),"") -> Lionel | D16: =COUNTIF(P16:AQ16,"p") -> 0 | E16: =COUNTIF(P16:AQ16,"PC") -> 0 | F16: =COUNTIF(P16:AQ16,"f") -> 0 | G16: =COUNTIF(P16:AQ16,"ast") -> 0 | H16: =COUNTIF(P16:AQ16,"cA") -> 0 | I16: =COUNTIF(P16:AQ16,"rtt") -> 0 | J16: =COUNTIF(P16:AQ16,"cex") -> 0 | K16: =COUNTIF(P16:AQ16,"res") -> 0 | L16: =COUNTIF(P16:AQ16,"mA") -> 0 | M16: =COUNTIF(P16:AQ16,"at") -> 0 | N16: =COUNTIF(P16:AQ16,"TAD") -> 0 | O16: =COUNTIF(P16:AQ16,"TP") -> 0
A17: =IFERROR(IF(config!E9="","",config!E9),"") -> N011045 | B17: =IFERROR(IF(config!F9="","",config!F9),"") -> SIGALA | C17: =IFERROR(IF(config!G9="","",config!G9),"") -> Jean-Christohpe | D17: =COUNTIF(P17:AQ17,"p") -> 0 | E17: =COUNTIF(P17:AQ17,"PC") -> 0 | F17: =COUNTIF(P17:AQ17,"f") -> 0 | G17: =COUNTIF(P17:AQ17,"ast") -> 0 | H17: =COUNTIF(P17:AQ17,"cA") -> 0 | I17: =COUNTIF(P17:AQ17,"rtt") -> 0 | J17: =COUNTIF(P17:AQ17,"cex") -> 0 | K17: =COUNTIF(P17:AQ17,"res") -> 0 | L17: =COUNTIF(P17:AQ17,"mA") -> 0 | M17: =COUNTIF(P17:AQ17,"at") -> 0 | N17: =COUNTIF(P17:AQ17,"TAD") -> 0 | O17: =COUNTIF(P17:AQ17,"TP") -> 0
A18: =IFERROR(IF(config!E10="","",config!E10),"") -> N010036 | B18: =IFERROR(IF(config!F10="","",config!F10),"") -> BETTINGER | C18: =IFERROR(IF(config!G10="","",config!G10),"") -> Philippe | D18: =COUNTIF(P18:AQ18,"p") -> 0 | E18: =COUNTIF(P18:AQ18,"PC") -> 0 | F18: =COUNTIF(P18:AQ18,"f") -> 0 | G18: =COUNTIF(P18:AQ18,"ast") -> 0 | H18: =COUNTIF(P18:AQ18,"cA") -> 6 | I18: =COUNTIF(P18:AQ18,"rtt") -> 2 | J18: =COUNTIF(P18:AQ18,"cex") -> 12 | K18: =COUNTIF(P18:AQ18,"res") -> 0 | L18: =COUNTIF(P18:AQ18,"mA") -> 0 | M18: =COUNTIF(P18:AQ18,"at") -> 0 | N18: =COUNTIF(P18:AQ18,"TAD") -> 0 | O18: =COUNTIF(P18:AQ18,"TP") -> 0 | Q18: CEX | R18: CEX | S18: CEX | T18: CEX | U18: CEX | X18: CEX | Y18: CEX | Z18: CEX | AA18: CEX | AB18: CEX | AE18: CEX | AF18: CEX | AG18: CA | AH18: CA | AI18: CA | AL18: CA | AM18: CA | AN18: RTT | AO18: RTT | AP18: CA
A19: =IFERROR(IF(config!E11="","",config!E11),"") -> N015967 | B19: =IFERROR(IF(config!F11="","",config!F11),"") -> TUCOULET | C19: =IFERROR(IF(config!G11="","",config!G11),"") -> Dorian | D19: =COUNTIF(P19:AQ19,"p") -> 0 | E19: =COUNTIF(P19:AQ19,"PC") -> 0 | F19: =COUNTIF(P19:AQ19,"f") -> 0 | G19: =COUNTIF(P19:AQ19,"ast") -> 0 | H19: =COUNTIF(P19:AQ19,"cA") -> 0 | I19: =COUNTIF(P19:AQ19,"rtt") -> 0 | J19: =COUNTIF(P19:AQ19,"cex") -> 0 | K19: =COUNTIF(P19:AQ19,"res") -> 0 | L19: =COUNTIF(P19:AQ19,"mA") -> 0 | M19: =COUNTIF(P19:AQ19,"at") -> 0 | N19: =COUNTIF(P19:AQ19,"TAD") -> 0 | O19: =COUNTIF(P19:AQ19,"TP") -> 0
A20: =IFERROR(IF(config!E12="","",config!E12),"") -> N017539 | B20: =IFERROR(IF(config!F12="","",config!F12),"") -> VRBOVSKA | C20: =IFERROR(IF(config!G12="","",config!G12),"") -> Xavier | D20: =COUNTIF(P20:AQ20,"p") -> 0 | E20: =COUNTIF(P20:AQ20,"PC") -> 6 | F20: =COUNTIF(P20:AQ20,"f") -> 0 | G20: =COUNTIF(P20:AQ20,"ast") -> 0 | H20: =COUNTIF(P20:AQ20,"cA") -> 0 | I20: =COUNTIF(P20:AQ20,"rtt") -> 0 | J20: =COUNTIF(P20:AQ20,"cex") -> 0 | K20: =COUNTIF(P20:AQ20,"res") -> 0 | L20: =COUNTIF(P20:AQ20,"mA") -> 0 | M20: =COUNTIF(P20:AQ20,"at") -> 0 | N20: =COUNTIF(P20:AQ20,"TAD") -> 0 | O20: =COUNTIF(P20:AQ20,"TP") -> 0 | AE20: PC | AF20: PC | AG20: PC | AH20: PC | AI20: PC | AN20: PC
A21: =IFERROR(IF(config!E13="","",config!E13),"") -> MAINTENANCE
A22: =IFERROR(IF(config!E14="","",config!E14),"") -> SURVEILLANT DE TRAVAUX
A23: =IFERROR(IF(config!E15="","",config!E15),"") -> C004587 | B23: =IFERROR(IF(config!F15="","",config!F15),"") -> BOURGOIN | C23: =IFERROR(IF(config!G15="","",config!G15),"") -> Jean-Baptiste | D23: =COUNTIF(P23:AQ23,"p") -> 0 | E23: =COUNTIF(P23:AQ23,"PC") -> 0 | F23: =COUNTIF(P23:AQ23,"f") -> 0 | G23: =COUNTIF(P23:AQ23,"ast") -> 0 | H23: =COUNTIF(P23:AQ23,"cA") -> 0 | I23: =COUNTIF(P23:AQ23,"rtt") -> 0 | J23: =COUNTIF(P23:AQ23,"cex") -> 0 | K23: =COUNTIF(P23:AQ23,"res") -> 0 | L23: =COUNTIF(P23:AQ23,"mA") -> 0 | M23: =COUNTIF(P23:AQ23,"at") -> 0 | N23: =COUNTIF(P23:AQ23,"TAD") -> 0 | O23: =COUNTIF(P23:AQ23,"TP") -> 0
A24: =IFERROR(IF(config!E16="","",config!E16),"") -> N02645 | B24: =IFERROR(IF(config!F16="","",config!F16),"") -> MERCADIEU | C24: =IFERROR(IF(config!G16="","",config!G16),"") -> Baptiste | D24: =COUNTIF(P24:AQ24,"p") -> 0 | E24: =COUNTIF(P24:AQ24,"PC") -> 0 | F24: =COUNTIF(P24:AQ24,"f") -> 0 | G24: =COUNTIF(P24:AQ24,"ast") -> 0 | H24: =COUNTIF(P24:AQ24,"cA") -> 0 | I24: =COUNTIF(P24:AQ24,"rtt") -> 0 | J24: =COUNTIF(P24:AQ24,"cex") -> 0 | K24: =COUNTIF(P24:AQ24,"res") -> 0 | L24: =COUNTIF(P24:AQ24,"mA") -> 0 | M24: =COUNTIF(P24:AQ24,"at") -> 0 | N24: =COUNTIF(P24:AQ24,"TAD") -> 0 | O24: =COUNTIF(P24:AQ24,"TP") -> 0
A25: =IFERROR(IF(config!E17="","",config!E17),"") -> ASDP
A26: =IFERROR(IF(config!E18="","",config!E18),"") -> C004845 | B26: =IFERROR(IF(config!F18="","",config!F18),"") -> GARCIA | C26: =IFERROR(IF(config!G18="","",config!G18),"") -> Yoan | D26: =COUNTIF(P26:AQ26,"p") -> 0 | E26: =COUNTIF(P26:AQ26,"PC") -> 0 | F26: =COUNTIF(P26:AQ26,"f") -> 0 | G26: =COUNTIF(P26:AQ26,"ast") -> 0 | H26: =COUNTIF(P26:AQ26,"cA") -> 0 | I26: =COUNTIF(P26:AQ26,"rtt") -> 0 | J26: =COUNTIF(P26:AQ26,"cex") -> 0 | K26: =COUNTIF(P26:AQ26,"res") -> 0 | L26: =COUNTIF(P26:AQ26,"mA") -> 0 | M26: =COUNTIF(P26:AQ26,"at") -> 0 | N26: =COUNTIF(P26:AQ26,"TAD") -> 0 | O26: =COUNTIF(P26:AQ26,"TP") -> 0
A27: =IFERROR(IF(config!E19="","",config!E19),"") -> C005015 | B27: =IFERROR(IF(config!F19="","",config!F19),"") -> LARROUDE | C27: =IFERROR(IF(config!G19="","",config!G19),"") -> Christophe | D27: =COUNTIF(P27:AQ27,"p") -> 0 | E27: =COUNTIF(P27:AQ27,"PC") -> 5 | F27: =COUNTIF(P27:AQ27,"f") -> 0 | G27: =COUNTIF(P27:AQ27,"ast") -> 0 | H27: =COUNTIF(P27:AQ27,"cA") -> 0 | I27: =COUNTIF(P27:AQ27,"rtt") -> 0 | J27: =COUNTIF(P27:AQ27,"cex") -> 0 | K27: =COUNTIF(P27:AQ27,"res") -> 0 | L27: =COUNTIF(P27:AQ27,"mA") -> 0 | M27: =COUNTIF(P27:AQ27,"at") -> 0 | N27: =COUNTIF(P27:AQ27,"TAD") -> 0 | O27: =COUNTIF(P27:AQ27,"TP") -> 0 | Q27: PC | R27: PC | S27: PC | T27: PC | U27: PC
A28: =IFERROR(IF(config!E20="","",config!E20),"") -> N020065 | B28: =IFERROR(IF(config!F20="","",config!F20),"") -> SAMITIER | C28: =IFERROR(IF(config!G20="","",config!G20),"") -> Beatrice | D28: =COUNTIF(P28:AQ28,"p") -> 0 | E28: =COUNTIF(P28:AQ28,"PC") -> 0 | F28: =COUNTIF(P28:AQ28,"f") -> 0 | G28: =COUNTIF(P28:AQ28,"ast") -> 0 | H28: =COUNTIF(P28:AQ28,"cA") -> 0 | I28: =COUNTIF(P28:AQ28,"rtt") -> 0 | J28: =COUNTIF(P28:AQ28,"cex") -> 0 | K28: =COUNTIF(P28:AQ28,"res") -> 0 | L28: =COUNTIF(P28:AQ28,"mA") -> 0 | M28: =COUNTIF(P28:AQ28,"at") -> 0 | N28: =COUNTIF(P28:AQ28,"TAD") -> 0 | O28: =COUNTIF(P28:AQ28,"TP") -> 0
A29: =IFERROR(IF(config!E21="","",config!E21),"") -> C005216 | B29: =IFERROR(IF(config!F21="","",config!F21),"") -> PIEL | C29: =IFERROR(IF(config!G21="","",config!G21),"") -> Frédy | D29: =COUNTIF(P29:AQ29,"p") -> 0 | E29: =COUNTIF(P29:AQ29,"PC") -> 0 | F29: =COUNTIF(P29:AQ29,"f") -> 0 | G29: =COUNTIF(P29:AQ29,"ast") -> 0 | H29: =COUNTIF(P29:AQ29,"cA") -> 0 | I29: =COUNTIF(P29:AQ29,"rtt") -> 0 | J29: =COUNTIF(P29:AQ29,"cex") -> 0 | K29: =COUNTIF(P29:AQ29,"res") -> 0 | L29: =COUNTIF(P29:AQ29,"mA") -> 0 | M29: =COUNTIF(P29:AQ29,"at") -> 0 | N29: =COUNTIF(P29:AQ29,"TAD") -> 0 | O29: =COUNTIF(P29:AQ29,"TP") -> 0
A30: =IFERROR(IF(config!E22="","",config!E22),"") -> PROPRETE
A31: =IFERROR(IF(config!E23="","",config!E23),"") -> JN020502 | B31: =IFERROR(IF(config!F23="","",config!F23),"") -> GOURVIAT | C31: =IFERROR(IF(config!G23="","",config!G23),"") -> Annabelle | D31: =COUNTIF(P31:AQ31,"p") -> 0 | E31: =COUNTIF(P31:AQ31,"PC") -> 0 | F31: =COUNTIF(P31:AQ31,"f") -> 0 | G31: =COUNTIF(P31:AQ31,"ast") -> 0 | H31: =COUNTIF(P31:AQ31,"cA") -> 0 | I31: =COUNTIF(P31:AQ31,"rtt") -> 0 | J31: =COUNTIF(P31:AQ31,"cex") -> 0 | K31: =COUNTIF(P31:AQ31,"res") -> 0 | L31: =COUNTIF(P31:AQ31,"mA") -> 0 | M31: =COUNTIF(P31:AQ31,"at") -> 0 | N31: =COUNTIF(P31:AQ31,"TAD") -> 0 | O31: =COUNTIF(P31:AQ31,"TP") -> 0
A32: =IFERROR(IF(config!E24="","",config!E24),"") -> JT032516 | B32: =IFERROR(IF(config!F24="","",config!F24),"") -> LARTIGUE | C32: =IFERROR(IF(config!G24="","",config!G24),"") -> Laura | D32: =COUNTIF(P32:AQ32,"p") -> 0 | E32: =COUNTIF(P32:AQ32,"PC") -> 0 | F32: =COUNTIF(P32:AQ32,"f") -> 0 | G32: =COUNTIF(P32:AQ32,"ast") -> 0 | H32: =COUNTIF(P32:AQ32,"cA") -> 0 | I32: =COUNTIF(P32:AQ32,"rtt") -> 0 | J32: =COUNTIF(P32:AQ32,"cex") -> 0 | K32: =COUNTIF(P32:AQ32,"res") -> 0 | L32: =COUNTIF(P32:AQ32,"mA") -> 0 | M32: =COUNTIF(P32:AQ32,"at") -> 0 | N32: =COUNTIF(P32:AQ32,"TAD") -> 0 | O32: =COUNTIF(P32:AQ32,"TP") -> 0
A33: =IFERROR(IF(config!E25="","",config!E25),"") -> JN010897 | B33: =IFERROR(IF(config!F25="","",config!F25),"") -> TRIQUENEAUX | C33: =IFERROR(IF(config!G25="","",config!G25),"") -> Benoit | D33: =COUNTIF(P33:AQ33,"p") -> 0 | E33: =COUNTIF(P33:AQ33,"PC") -> 0 | F33: =COUNTIF(P33:AQ33,"f") -> 0 | G33: =COUNTIF(P33:AQ33,"ast") -> 0 | H33: =COUNTIF(P33:AQ33,"cA") -> 0 | I33: =COUNTIF(P33:AQ33,"rtt") -> 0 | J33: =COUNTIF(P33:AQ33,"cex") -> 0 | K33: =COUNTIF(P33:AQ33,"res") -> 0 | L33: =COUNTIF(P33:AQ33,"mA") -> 0 | M33: =COUNTIF(P33:AQ33,"at") -> 0 | N33: =COUNTIF(P33:AQ33,"TAD") -> 0 | O33: =COUNTIF(P33:AQ33,"TP") -> 0
A34: =IFERROR(IF(config!E26="","",config!E26),"") -> JN010381 | B34: =IFERROR(IF(config!F26="","",config!F26),"") -> ESPERON | C34: =IFERROR(IF(config!G26="","",config!G26),"") -> Alain | D34: =COUNTIF(P34:AQ34,"p") -> 0 | E34: =COUNTIF(P34:AQ34,"PC") -> 0 | F34: =COUNTIF(P34:AQ34,"f") -> 0 | G34: =COUNTIF(P34:AQ34,"ast") -> 0 | H34: =COUNTIF(P34:AQ34,"cA") -> 0 | I34: =COUNTIF(P34:AQ34,"rtt") -> 0 | J34: =COUNTIF(P34:AQ34,"cex") -> 0 | K34: =COUNTIF(P34:AQ34,"res") -> 0 | L34: =COUNTIF(P34:AQ34,"mA") -> 0 | M34: =COUNTIF(P34:AQ34,"at") -> 0 | N34: =COUNTIF(P34:AQ34,"TAD") -> 0 | O34: =COUNTIF(P34:AQ34,"TP") -> 0
A35: =IFERROR(IF(config!E27="","",config!E27),"") -> JN010750 | B35: =IFERROR(IF(config!F27="","",config!F27),"") -> ROUGLAN | C35: =IFERROR(IF(config!G27="","",config!G27),"") -> William | D35: =COUNTIF(P35:AQ35,"p") -> 0 | E35: =COUNTIF(P35:AQ35,"PC") -> 0 | F35: =COUNTIF(P35:AQ35,"f") -> 0 | G35: =COUNTIF(P35:AQ35,"ast") -> 0 | H35: =COUNTIF(P35:AQ35,"cA") -> 0 | I35: =COUNTIF(P35:AQ35,"rtt") -> 0 | J35: =COUNTIF(P35:AQ35,"cex") -> 0 | K35: =COUNTIF(P35:AQ35,"res") -> 0 | L35: =COUNTIF(P35:AQ35,"mA") -> 0 | M35: =COUNTIF(P35:AQ35,"at") -> 0 | N35: =COUNTIF(P35:AQ35,"TAD") -> 0 | O35: =COUNTIF(P35:AQ35,"TP") -> 0
A36: =IFERROR(IF(config!E28="","",config!E28),"") -> JN010461 | B36: =IFERROR(IF(config!F28="","",config!F28),"") -> NOURRI | C36: =IFERROR(IF(config!G28="","",config!G28),"") -> Danny | D36: =COUNTIF(P36:AQ36,"p") -> 0 | E36: =COUNTIF(P36:AQ36,"PC") -> 0 | F36: =COUNTIF(P36:AQ36,"f") -> 0 | G36: =COUNTIF(P36:AQ36,"ast") -> 0 | H36: =COUNTIF(P36:AQ36,"cA") -> 0 | I36: =COUNTIF(P36:AQ36,"rtt") -> 0 | J36: =COUNTIF(P36:AQ36,"cex") -> 0 | K36: =COUNTIF(P36:AQ36,"res") -> 0 | L36: =COUNTIF(P36:AQ36,"mA") -> 0 | M36: =COUNTIF(P36:AQ36,"at") -> 0 | N36: =COUNTIF(P36:AQ36,"TAD") -> 0 | O36: =COUNTIF(P36:AQ36,"TP") -> 0
A37: =IFERROR(IF(config!E29="","",config!E29),"") -> REGIE
A38: =IFERROR(IF(config!E30="","",config!E30),"") -> AGENTS VOIRIE | AS38: VOIRIE
A39: =IFERROR(IF(config!E31="","",config!E31),"") -> JT028103 | B39: =IFERROR(IF(config!F31="","",config!F31),"") -> BERRIO-GAUDNER | C39: =IFERROR(IF(config!G31="","",config!G31),"") -> Jacques | D39: =COUNTIF(P39:AQ39,"p") -> 0 | E39: =COUNTIF(P39:AQ39,"PC") -> 0 | F39: =COUNTIF(P39:AQ39,"f") -> 0 | G39: =COUNTIF(P39:AQ39,"ast") -> 0 | H39: =COUNTIF(P39:AQ39,"cA") -> 0 | I39: =COUNTIF(P39:AQ39,"rtt") -> 0 | J39: =COUNTIF(P39:AQ39,"cex") -> 0 | K39: =COUNTIF(P39:AQ39,"res") -> 0 | L39: =COUNTIF(P39:AQ39,"mA") -> 0 | M39: =COUNTIF(P39:AQ39,"at") -> 0 | N39: =COUNTIF(P39:AQ39,"TAD") -> 0 | O39: =COUNTIF(P39:AQ39,"TP") -> 0 | AS39: P | AT39: PC | AU39: F | AV39: AST | AW39: CA | AX39: RTT | AY39: CEX | AZ39: R | BA39: M | BB39: AT | BC39: TP
A40: =IFERROR(IF(config!E32="","",config!E32),"") -> C002908 | B40: =IFERROR(IF(config!F32="","",config!F32),"") -> FONTENEAU | C40: =IFERROR(IF(config!G32="","",config!G32),"") -> Fabrice | D40: =COUNTIF(P40:AQ40,"p") -> 0 | E40: =COUNTIF(P40:AQ40,"PC") -> 1 | F40: =COUNTIF(P40:AQ40,"f") -> 0 | G40: =COUNTIF(P40:AQ40,"ast") -> 0 | H40: =COUNTIF(P40:AQ40,"cA") -> 0 | I40: =COUNTIF(P40:AQ40,"rtt") -> 0 | J40: =COUNTIF(P40:AQ40,"cex") -> 0 | K40: =COUNTIF(P40:AQ40,"res") -> 0 | L40: =COUNTIF(P40:AQ40,"mA") -> 0 | M40: =COUNTIF(P40:AQ40,"at") -> 0 | N40: =COUNTIF(P40:AQ40,"TAD") -> 0 | O40: =COUNTIF(P40:AQ40,"TP") -> 0 | Q40: PC | AS40: =COUNTIF(P39:AQ49,"p") -> 0 | AT40: =COUNTIF(P39:AQ49,"pc") -> 1 | AU40: =COUNTIF(P39:AQ49,"f") -> 0 | AV40: =COUNTIF(P39:AQ49,"ast") -> 0 | AW40: =COUNTIF(P39:AQ49,"cA") -> 0 | AX40: =COUNTIF(P39:AQ49,"rtt") -> 0 | AY40: =COUNTIF(P39:AQ49,"cex") -> 0 | AZ40: =COUNTIF(P39:AQ49,"RES") -> 0 | BA40: =COUNTIF(P39:AQ49,"MA") -> 0 | BB40: =COUNTIF(P39:AQ49,"at") -> 28 | BC40: =COUNTIF(P39:AQ49,"TP") -> 0
A41: =IFERROR(IF(config!E33="","",config!E33),"") -> C004504 | B41: =IFERROR(IF(config!F33="","",config!F33),"") -> GUIJARRO | C41: =IFERROR(IF(config!G33="","",config!G33),"") -> Juan-Pédro | D41: =COUNTIF(P41:AQ41,"p") -> 0 | E41: =COUNTIF(P41:AQ41,"PC") -> 0 | F41: =COUNTIF(P41:AQ41,"f") -> 0 | G41: =COUNTIF(P41:AQ41,"ast") -> 0 | H41: =COUNTIF(P41:AQ41,"cA") -> 0 | I41: =COUNTIF(P41:AQ41,"rtt") -> 0 | J41: =COUNTIF(P41:AQ41,"cex") -> 0 | K41: =COUNTIF(P41:AQ41,"res") -> 0 | L41: =COUNTIF(P41:AQ41,"mA") -> 0 | M41: =COUNTIF(P41:AQ41,"at") -> 0 | N41: =COUNTIF(P41:AQ41,"TAD") -> 0 | O41: =COUNTIF(P41:AQ41,"TP") -> 0
A42: =IFERROR(IF(config!E34="","",config!E34),"") -> T028198 | B42: =IFERROR(IF(config!F34="","",config!F34),"") -> GOUREAU | C42: =IFERROR(IF(config!G34="","",config!G34),"") -> Jonathan | D42: =COUNTIF(P42:AQ42,"p") -> 0 | E42: =COUNTIF(P42:AQ42,"PC") -> 0 | F42: =COUNTIF(P42:AQ42,"f") -> 0 | G42: =COUNTIF(P42:AQ42,"ast") -> 0 | H42: =COUNTIF(P42:AQ42,"cA") -> 0 | I42: =COUNTIF(P42:AQ42,"rtt") -> 0 | J42: =COUNTIF(P42:AQ42,"cex") -> 0 | K42: =COUNTIF(P42:AQ42,"res") -> 0 | L42: =COUNTIF(P42:AQ42,"mA") -> 0 | M42: =COUNTIF(P42:AQ42,"at") -> 0 | N42: =COUNTIF(P42:AQ42,"TAD") -> 0 | O42: =COUNTIF(P42:AQ42,"TP") -> 0
A43: =IFERROR(IF(config!E35="","",config!E35),"") -> C002986 | B43: =IFERROR(IF(config!F35="","",config!F35),"") -> LABORIE | C43: =IFERROR(IF(config!G35="","",config!G35),"") -> Jean-Louis | D43: =COUNTIF(P43:AQ43,"p") -> 0 | E43: =COUNTIF(P43:AQ43,"PC") -> 0 | F43: =COUNTIF(P43:AQ43,"f") -> 0 | G43: =COUNTIF(P43:AQ43,"ast") -> 0 | H43: =COUNTIF(P43:AQ43,"cA") -> 0 | I43: =COUNTIF(P43:AQ43,"rtt") -> 0 | J43: =COUNTIF(P43:AQ43,"cex") -> 0 | K43: =COUNTIF(P43:AQ43,"res") -> 0 | L43: =COUNTIF(P43:AQ43,"mA") -> 0 | M43: =COUNTIF(P43:AQ43,"at") -> 0 | N43: =COUNTIF(P43:AQ43,"TAD") -> 0 | O43: =COUNTIF(P43:AQ43,"TP") -> 0
...

Sheet Mars 2026
A1: =config!B7 -> 46082
A2: =config!C7 -> 46112
P4: =A1 -> 46082 | Q4: =P4+1 -> 46083 | R4: =Q4+1 -> 46084 | S4: =R4+1 -> 46085 | T4: =S4+1 -> 46086 | U4: =T4+1 -> 46087 | V4: =U4+1 -> 46088 | W4: =V4+1 -> 46089 | X4: =W4+1 -> 46090 | ... AT4: =AS4+1 -> 46112
A5: =TEXT(A1,"mmmmmmmmmmmm") -> mars
D8: TOTAL | AM8: ARRET EVP JAN
D9: P | E9: PC | F9: F | G9: AST | H9: CA | I9: RTT | J9: CEX | K9: R | L9: M | M9: AT | N9: TAD | O9: TP | P9: =IFERROR(WEEKDAY(P4),"") -> 1 | Q9: =IFERROR(WEEKDAY(Q4),"") -> 2 | R9: =IFERROR(WEEKDAY(R4),"") -> 3 | S9: =IFERROR(WEEKDAY(S4),"") -> 4 | T9: =IFERROR(WEEKDAY(T4),"") -> 5 | U9: =IFERROR(WEEKDAY(U4),"") -> 6 | V9: =IFERROR(WEEKDAY(V4),"") -> 7 | W9: =IFERROR(WEEKDAY(W4),"") -> 1 | ... AT9: =IFERROR(WEEKDAY(AT4),"") -> 3
A10: Matricule | B10: Nom | C10: Prénom | D10: PRESENCE | E10: PREV CONGES | F10: FORMATION | G10: ASTREINT | H10: CONGES ANNUEL | I10: RTT | J10: CONGES EXC | K10: RESERVE | L10: MALADIE | M10: ACCIDENT DE TRAVAIL | N10: TRAVAI A DISTANCE | O10: Tps partiel TH | P10: =DAY(P4) -> 1 | Q10: =DAY(Q4) -> 2 | R10: =DAY(R4) -> 3 | S10: =DAY(S4) -> 4 | T10: =DAY(T4) -> 5 | U10: =DAY(U4) -> 6 | V10: =DAY(V4) -> 7 | W10: =DAY(W4) -> 8 | ... AT10: =DAY(AT4) -> 31
A11: =IFERROR(IF(config!E3="","",config!E3),"") -> N019002 | B11: =IFERROR(IF(config!F3="","",config!F3),"") -> DEBREYNE | C11: =IFERROR(IF(config!G3="","",config!G3),"") -> Audrey | D11: =COUNTIF(P11:AS11,"p") -> 0 | E11: =COUNTIF(P11:AS11,"PC") -> 0 | F11: =COUNTIF(P11:AS11,"f") -> 0 | G11: =COUNTIF(P11:AS11,"ast") -> 0 | H11: =COUNTIF(P11:AS11,"cA") -> 0 | I11: =COUNTIF(P11:AS11,"rtt") -> 0 | J11: =COUNTIF(P11:AS11,"cex") -> 0 | K11: =COUNTIF(P11:AS11,"res") -> 0 | L11: =COUNTIF(P11:AS11,"mA") -> 0 | M11: =COUNTIF(P11:AS11,"at") -> 0 | N11: =COUNTIF(P11:AS11,"TAD") -> 0 | O11: =COUNTIF(P11:AS11,"TP") -> 0 | AV11: BUREAU
A12: =IFERROR(IF(config!E4="","",config!E4),"") -> N024050 | B12: =IFERROR(IF(config!F4="","",config!F4),"") -> LUTARD | C12: =IFERROR(IF(config!G4="","",config!G4),"") -> Karyne | D12: =COUNTIF(P12:AS12,"p") -> 0 | E12: =COUNTIF(P12:AS12,"PC") -> 15 | F12: =COUNTIF(P12:AS12,"f") -> 0 | G12: =COUNTIF(P12:AS12,"ast") -> 0 | H12: =COUNTIF(P12:AS12,"cA") -> 0 | I12: =COUNTIF(P12:AS12,"rtt") -> 0 | J12: =COUNTIF(P12:AS12,"cex") -> 0 | K12: =COUNTIF(P12:AS12,"res") -> 0 | L12: =COUNTIF(P12:AS12,"mA") -> 0 | M12: =COUNTIF(P12:AS12,"at") -> 0 | N12: =COUNTIF(P12:AS12,"TAD") -> 0 | O12: =COUNTIF(P12:AS12,"TP") -> 0 | X12: PC | Y12: PC | Z12: PC | AA12: PC | AB12: PC | AE12: PC | AF12: PC | AG12: PC | AH12: PC | AI12: PC | AL12: PC | AM12: PC | AN12: PC | AO12: PC | AP12: PC | AV12: P | AW12: PC | AX12: F | AY12: AST | AZ12: CA | BA12: RTT | BB12: CEX | BC12: R | BD12: M | BE12: AT | BF12: TP
A13: =IFERROR(IF(config!E5="","",config!E5),"") -> N018905 | B13: =IFERROR(IF(config!F5="","",config!F5),"") -> HAUTDECOEUR | C13: =IFERROR(IF(config!G5="","",config!G5),"") -> Laurence | D13: =COUNTIF(P13:AS13,"p") -> 0 | E13: =COUNTIF(P13:AS13,"PC") -> 0 | F13: =COUNTIF(P13:AS13,"f") -> 0 | G13: =COUNTIF(P13:AS13,"ast") -> 0 | H13: =COUNTIF(P13:AS13,"cA") -> 0 | I13: =COUNTIF(P13:AS13,"rtt") -> 0 | J13: =COUNTIF(P13:AS13,"cex") -> 0 | K13: =COUNTIF(P13:AS13,"res") -> 0 | L13: =COUNTIF(P13:AS13,"mA") -> 0 | M13: =COUNTIF(P13:AS13,"at") -> 0 | N13: =COUNTIF(P13:AS13,"TAD") -> 0 | O13: =COUNTIF(P13:AS13,"TP") -> 0 | AV13: =COUNTIF(P11:AS29,"p") -> 0 | AW13: =COUNTIF(P11:AS29,"PC") -> 15 | AX13: =COUNTIF(P11:AS29,"f") -> 0 | AY13: =COUNTIF(P11:AS29,"ast") -> 0 | AZ13: =COUNTIF(P11:AS29,"ca") -> 0 | BA13: =COUNTIF(P11:AS29,"rtt") -> 0 | BB13: =COUNTIF(P11:AS29,"CEX") -> 0 | BC13: =COUNTIF(P11:AS29,"RES") -> 0 | BD13: =COUNTIF(P11:AS29,"MA") -> 0 | BE13: =COUNTIF(P11:AS29,"AT") -> 0 | BF13: =COUNTIF(P11:AS29,"TP") -> 0
A14: =IFERROR(IF(config!E6="","",config!E6),"") -> N016820 | B14: =IFERROR(IF(config!F6="","",config!F6),"") -> GRENET | C14: =IFERROR(IF(config!G6="","",config!G6),"") -> Eric | D14: =COUNTIF(P14:AS14,"p") -> 0 | E14: =COUNTIF(P14:AS14,"PC") -> 0 | F14: =COUNTIF(P14:AS14,"f") -> 0 | G14: =COUNTIF(P14:AS14,"ast") -> 0 | H14: =COUNTIF(P14:AS14,"cA") -> 0 | I14: =COUNTIF(P14:AS14,"rtt") -> 0 | J14: =COUNTIF(P14:AS14,"cex") -> 0 | K14: =COUNTIF(P14:AS14,"res") -> 0 | L14: =COUNTIF(P14:AS14,"mA") -> 0 | M14: =COUNTIF(P14:AS14,"at") -> 0 | N14: =COUNTIF(P14:AS14,"TAD") -> 0 | O14: =COUNTIF(P14:AS14,"TP") -> 0
A15: =IFERROR(IF(config!E7="","",config!E7),"") -> C003285 | B15: =IFERROR(IF(config!F7="","",config!F7),"") -> FOURCADE | C15: =IFERROR(IF(config!G7="","",config!G7),"") -> Hervé | D15: =COUNTIF(P15:AS15,"p") -> 0 | E15: =COUNTIF(P15:AS15,"PC") -> 0 | F15: =COUNTIF(P15:AS15,"f") -> 0 | G15: =COUNTIF(P15:AS15,"ast") -> 0 | H15: =COUNTIF(P15:AS15,"cA") -> 0 | I15: =COUNTIF(P15:AS15,"rtt") -> 0 | J15: =COUNTIF(P15:AS15,"cex") -> 0 | K15: =COUNTIF(P15:AS15,"res") -> 0 | L15: =COUNTIF(P15:AS15,"mA") -> 0 | M15: =COUNTIF(P15:AS15,"at") -> 0 | N15: =COUNTIF(P15:AS15,"TAD") -> 0 | O15: =COUNTIF(P15:AS15,"TP") -> 0
A16: =IFERROR(IF(config!E8="","",config!E8),"") -> JT030845 | B16: =IFERROR(IF(config!F8="","",config!F8),"") -> GONCALVES | C16: =IFERROR(IF(config!G8="","",config!G8),"") -> Lionel | D16: =COUNTIF(P16:AS16,"p") -> 0 | E16: =COUNTIF(P16:AS16,"PC") -> 0 | F16: =COUNTIF(P16:AS16,"f") -> 0 | G16: =COUNTIF(P16:AS16,"ast") -> 0 | H16: =COUNTIF(P16:AS16,"cA") -> 0 | I16: =COUNTIF(P16:AS16,"rtt") -> 0 | J16: =COUNTIF(P16:AS16,"cex") -> 0 | K16: =COUNTIF(P16:AS16,"res") -> 0 | L16: =COUNTIF(P16:AS16,"mA") -> 0 | M16: =COUNTIF(P16:AS16,"at") -> 0 | N16: =COUNTIF(P16:AS16,"TAD") -> 0 | O16: =COUNTIF(P16:AS16,"TP") -> 0
A17: =IFERROR(IF(config!E9="","",config!E9),"") -> N011045 | B17: =IFERROR(IF(config!F9="","",config!F9),"") -> SIGALA | C17: =IFERROR(IF(config!G9="","",config!G9),"") -> Jean-Christohpe | D17: =COUNTIF(P17:AS17,"p") -> 0 | E17: =COUNTIF(P17:AS17,"PC") -> 0 | F17: =COUNTIF(P17:AS17,"f") -> 0 | G17: =COUNTIF(P17:AS17,"ast") -> 0 | H17: =COUNTIF(P17:AS17,"cA") -> 0 | I17: =COUNTIF(P17:AS17,"rtt") -> 0 | J17: =COUNTIF(P17:AS17,"cex") -> 0 | K17: =COUNTIF(P17:AS17,"res") -> 0 | L17: =COUNTIF(P17:AS17,"mA") -> 0 | M17: =COUNTIF(P17:AS17,"at") -> 0 | N17: =COUNTIF(P17:AS17,"TAD") -> 0 | O17: =COUNTIF(P17:AS17,"TP") -> 0
D18: =COUNTIF(P18:AS18,"p") -> 0 | E18: =COUNTIF(P18:AS18,"PC") -> 0 | F18: =COUNTIF(P18:AS18,"f") -> 0 | G18: =COUNTIF(P18:AS18,"ast") -> 0 | H18: =COUNTIF(P18:AS18,"cA") -> 0 | I18: =COUNTIF(P18:AS18,"rtt") -> 0 | J18: =COUNTIF(P18:AS18,"cex") -> 0 | K18: =COUNTIF(P18:AS18,"res") -> 0 | L18: =COUNTIF(P18:AS18,"mA") -> 0 | M18: =COUNTIF(P18:AS18,"at") -> 0 | N18: =COUNTIF(P18:AS18,"TAD") -> 0 | O18: =COUNTIF(P18:AS18,"TP") -> 0
A19: =IFERROR(IF(config!E11="","",config!E11),"") -> N015967 | B19: =IFERROR(IF(config!F11="","",config!F11),"") -> TUCOULET | C19: =IFERROR(IF(config!G11="","",config!G11),"") -> Dorian | D19: =COUNTIF(P19:AS19,"p") -> 0 | E19: =COUNTIF(P19:AS19,"PC") -> 0 | F19: =COUNTIF(P19:AS19,"f") -> 0 | G19: =COUNTIF(P19:AS19,"ast") -> 0 | H19: =COUNTIF(P19:AS19,"cA") -> 0 | I19: =COUNTIF(P19:AS19,"rtt") -> 0 | J19: =COUNTIF(P19:AS19,"cex") -> 0 | K19: =COUNTIF(P19:AS19,"res") -> 0 | L19: =COUNTIF(P19:AS19,"mA") -> 0 | M19: =COUNTIF(P19:AS19,"at") -> 0 | N19: =COUNTIF(P19:AS19,"TAD") -> 0 | O19: =COUNTIF(P19:AS19,"TP") -> 0
A20: =IFERROR(IF(config!E12="","",config!E12),"") -> N017539 | B20: =IFERROR(IF(config!F12="","",config!F12),"") -> VRBOVSKA | C20: =IFERROR(IF(config!G12="","",config!G12),"") -> Xavier | D20: =COUNTIF(P20:AS20,"p") -> 0 | E20: =COUNTIF(P20:AS20,"PC") -> 0 | F20: =COUNTIF(P20:AS20,"f") -> 0 | G20: =COUNTIF(P20:AS20,"ast") -> 0 | H20: =COUNTIF(P20:AS20,"cA") -> 0 | I20: =COUNTIF(P20:AS20,"rtt") -> 0 | J20: =COUNTIF(P20:AS20,"cex") -> 0 | K20: =COUNTIF(P20:AS20,"res") -> 0 | L20: =COUNTIF(P20:AS20,"mA") -> 0 | M20: =COUNTIF(P20:AS20,"at") -> 0 | N20: =COUNTIF(P20:AS20,"TAD") -> 0 | O20: =COUNTIF(P20:AS20,"TP") -> 0
A21: =IFERROR(IF(config!E13="","",config!E13),"") -> MAINTENANCE
A22: =IFERROR(IF(config!E14="","",config!E14),"") -> SURVEILLANT DE TRAVAUX
A23: =IFERROR(IF(config!E15="","",config!E15),"") -> C004587 | B23: =IFERROR(IF(config!F15="","",config!F15),"") -> BOURGOIN | C23: =IFERROR(IF(config!G15="","",config!G15),"") -> Jean-Baptiste | D23: =COUNTIF(P23:AS23,"p") -> 0 | E23: =COUNTIF(P23:AS23,"PC") -> 0 | F23: =COUNTIF(P23:AS23,"f") -> 0 | G23: =COUNTIF(P23:AS23,"ast") -> 0 | H23: =COUNTIF(P23:AS23,"cA") -> 0 | I23: =COUNTIF(P23:AS23,"rtt") -> 0 | J23: =COUNTIF(P23:AS23,"cex") -> 0 | K23: =COUNTIF(P23:AS23,"res") -> 0 | L23: =COUNTIF(P23:AS23,"mA") -> 0 | M23: =COUNTIF(P23:AS23,"at") -> 0 | N23: =COUNTIF(P23:AS23,"TAD") -> 0 | O23: =COUNTIF(P23:AS23,"TP") -> 0
A24: =IFERROR(IF(config!E16="","",config!E16),"") -> N02645 | B24: =IFERROR(IF(config!F16="","",config!F16),"") -> MERCADIEU | C24: =IFERROR(IF(config!G16="","",config!G16),"") -> Baptiste | D24: =COUNTIF(P24:AS24,"p") -> 0 | E24: =COUNTIF(P24:AS24,"PC") -> 0 | F24: =COUNTIF(P24:AS24,"f") -> 0 | G24: =COUNTIF(P24:AS24,"ast") -> 0 | H24: =COUNTIF(P24:AS24,"cA") -> 0 | I24: =COUNTIF(P24:AS24,"rtt") -> 0 | J24: =COUNTIF(P24:AS24,"cex") -> 0 | K24: =COUNTIF(P24:AS24,"res") -> 0 | L24: =COUNTIF(P24:AS24,"mA") -> 0 | M24: =COUNTIF(P24:AS24,"at") -> 0 | N24: =COUNTIF(P24:AS24,"TAD") -> 0 | O24: =COUNTIF(P24:AS24,"TP") -> 0
A25: =IFERROR(IF(config!E17="","",config!E17),"") -> ASDP
A26: =IFERROR(IF(config!E18="","",config!E18),"") -> C004845 | B26: =IFERROR(IF(config!F18="","",config!F18),"") -> GARCIA | C26: =IFERROR(IF(config!G18="","",config!G18),"") -> Yoan | D26: =COUNTIF(P26:AS26,"p") -> 0 | E26: =COUNTIF(P26:AS26,"PC") -> 0 | F26: =COUNTIF(P26:AS26,"f") -> 0 | G26: =COUNTIF(P26:AS26,"ast") -> 0 | H26: =COUNTIF(P26:AS26,"cA") -> 0 | I26: =COUNTIF(P26:AS26,"rtt") -> 0 | J26: =COUNTIF(P26:AS26,"cex") -> 0 | K26: =COUNTIF(P26:AS26,"res") -> 0 | L26: =COUNTIF(P26:AS26,"mA") -> 0 | M26: =COUNTIF(P26:AS26,"at") -> 0 | N26: =COUNTIF(P26:AS26,"TAD") -> 0 | O26: =COUNTIF(P26:AS26,"TP") -> 0
A27: =IFERROR(IF(config!E19="","",config!E19),"") -> C005015 | B27: =IFERROR(IF(config!F19="","",config!F19),"") -> LARROUDE | C27: =IFERROR(IF(config!G19="","",config!G19),"") -> Christophe | D27: =COUNTIF(P27:AS27,"p") -> 0 | E27: =COUNTIF(P27:AS27,"PC") -> 0 | F27: =COUNTIF(P27:AS27,"f") -> 0 | G27: =COUNTIF(P27:AS27,"ast") -> 0 | H27: =COUNTIF(P27:AS27,"cA") -> 0 | I27: =COUNTIF(P27:AS27,"rtt") -> 0 | J27: =COUNTIF(P27:AS27,"cex") -> 0 | K27: =COUNTIF(P27:AS27,"res") -> 0 | L27: =COUNTIF(P27:AS27,"mA") -> 0 | M27: =COUNTIF(P27:AS27,"at") -> 0 | N27: =COUNTIF(P27:AS27,"TAD") -> 0 | O27: =COUNTIF(P27:AS27,"TP") -> 0
A28: =IFERROR(IF(config!E20="","",config!E20),"") -> N020065 | B28: =IFERROR(IF(config!F20="","",config!F20),"") -> SAMITIER | C28: =IFERROR(IF(config!G20="","",config!G20),"") -> Beatrice | D28: =COUNTIF(P28:AS28,"p") -> 0 | E28: =COUNTIF(P28:AS28,"PC") -> 0 | F28: =COUNTIF(P28:AS28,"f") -> 0 | G28: =COUNTIF(P28:AS28,"ast") -> 0 | H28: =COUNTIF(P28:AS28,"cA") -> 0 | I28: =COUNTIF(P28:AS28,"rtt") -> 0 | J28: =COUNTIF(P28:AS28,"cex") -> 0 | K28: =COUNTIF(P28:AS28,"res") -> 0 | L28: =COUNTIF(P28:AS28,"mA") -> 0 | M28: =COUNTIF(P28:AS28,"at") -> 0 | N28: =COUNTIF(P28:AS28,"TAD") -> 0 | O28: =COUNTIF(P28:AS28,"TP") -> 0
A29: =IFERROR(IF(config!E21="","",config!E21),"") -> C005216 | B29: =IFERROR(IF(config!F21="","",config!F21),"") -> PIEL | C29: =IFERROR(IF(config!G21="","",config!G21),"") -> Frédy | D29: =COUNTIF(P29:AS29,"p") -> 0 | E29: =COUNTIF(P29:AS29,"PC") -> 0 | F29: =COUNTIF(P29:AS29,"f") -> 0 | G29: =COUNTIF(P29:AS29,"ast") -> 0 | H29: =COUNTIF(P29:AS29,"cA") -> 0 | I29: =COUNTIF(P29:AS29,"rtt") -> 0 | J29: =COUNTIF(P29:AS29,"cex") -> 0 | K29: =COUNTIF(P29:AS29,"res") -> 0 | L29: =COUNTIF(P29:AS29,"mA") -> 0 | M29: =COUNTIF(P29:AS29,"at") -> 0 | N29: =COUNTIF(P29:AS29,"TAD") -> 0 | O29: =COUNTIF(P29:AS29,"TP") -> 0
A30: =IFERROR(IF(config!E22="","",config!E22),"") -> PROPRETE
A31: =IFERROR(IF(config!E23="","",config!E23),"") -> JN020502 | B31: =IFERROR(IF(config!F23="","",config!F23),"") -> GOURVIAT | C31: =IFERROR(IF(config!G23="","",config!G23),"") -> Annabelle | D31: =COUNTIF(P31:AS31,"p") -> 0 | E31: =COUNTIF(P31:AS31,"PC") -> 0 | F31: =COUNTIF(P31:AS31,"f") -> 0 | G31: =COUNTIF(P31:AS31,"ast") -> 0 | H31: =COUNTIF(P31:AS31,"cA") -> 0 | I31: =COUNTIF(P31:AS31,"rtt") -> 0 | J31: =COUNTIF(P31:AS31,"cex") -> 0 | K31: =COUNTIF(P31:AS31,"res") -> 0 | L31: =COUNTIF(P31:AS31,"mA") -> 0 | M31: =COUNTIF(P31:AS31,"at") -> 0 | N31: =COUNTIF(P31:AS31,"TAD") -> 0 | O31: =COUNTIF(P31:AS31,"TP") -> 0
A32: =IFERROR(IF(config!E24="","",config!E24),"") -> JT032516 | B32: =IFERROR(IF(config!F24="","",config!F24),"") -> LARTIGUE | C32: =IFERROR(IF(config!G24="","",config!G24),"") -> Laura | D32: =COUNTIF(P32:AS32,"p") -> 0 | E32: =COUNTIF(P32:AS32,"PC") -> 0 | F32: =COUNTIF(P32:AS32,"f") -> 0 | G32: =COUNTIF(P32:AS32,"ast") -> 0 | H32: =COUNTIF(P32:AS32,"cA") -> 0 | I32: =COUNTIF(P32:AS32,"rtt") -> 0 | J32: =COUNTIF(P32:AS32,"cex") -> 0 | K32: =COUNTIF(P32:AS32,"res") -> 0 | L32: =COUNTIF(P32:AS32,"mA") -> 0 | M32: =COUNTIF(P32:AS32,"at") -> 0 | N32: =COUNTIF(P32:AS32,"TAD") -> 0 | O32: =COUNTIF(P32:AS32,"TP") -> 0
A33: =IFERROR(IF(config!E25="","",config!E25),"") -> JN010897 | B33: =IFERROR(IF(config!F25="","",config!F25),"") -> TRIQUENEAUX | C33: =IFERROR(IF(config!G25="","",config!G25),"") -> Benoit | D33: =COUNTIF(P33:AS33,"p") -> 0 | E33: =COUNTIF(P33:AS33,"PC") -> 0 | F33: =COUNTIF(P33:AS33,"f") -> 0 | G33: =COUNTIF(P33:AS33,"ast") -> 0 | H33: =COUNTIF(P33:AS33,"cA") -> 0 | I33: =COUNTIF(P33:AS33,"rtt") -> 0 | J33: =COUNTIF(P33:AS33,"cex") -> 0 | K33: =COUNTIF(P33:AS33,"res") -> 0 | L33: =COUNTIF(P33:AS33,"mA") -> 0 | M33: =COUNTIF(P33:AS33,"at") -> 0 | N33: =COUNTIF(P33:AS33,"TAD") -> 0 | O33: =COUNTIF(P33:AS33,"TP") -> 0
A34: =IFERROR(IF(config!E26="","",config!E26),"") -> JN010381 | B34: =IFERROR(IF(config!F26="","",config!F26),"") -> ESPERON | C34: =IFERROR(IF(config!G26="","",config!G26),"") -> Alain | D34: =COUNTIF(P34:AS34,"p") -> 0 | E34: =COUNTIF(P34:AS34,"PC") -> 0 | F34: =COUNTIF(P34:AS34,"f") -> 0 | G34: =COUNTIF(P34:AS34,"ast") -> 0 | H34: =COUNTIF(P34:AS34,"cA") -> 0 | I34: =COUNTIF(P34:AS34,"rtt") -> 0 | J34: =COUNTIF(P34:AS34,"cex") -> 0 | K34: =COUNTIF(P34:AS34,"res") -> 0 | L34: =COUNTIF(P34:AS34,"mA") -> 0 | M34: =COUNTIF(P34:AS34,"at") -> 0 | N34: =COUNTIF(P34:AS34,"TAD") -> 0 | O34: =COUNTIF(P34:AS34,"TP") -> 0
A35: =IFERROR(IF(config!E27="","",config!E27),"") -> JN010750 | B35: =IFERROR(IF(config!F27="","",config!F27),"") -> ROUGLAN | C35: =IFERROR(IF(config!G27="","",config!G27),"") -> William | D35: =COUNTIF(P35:AS35,"p") -> 0 | E35: =COUNTIF(P35:AS35,"PC") -> 0 | F35: =COUNTIF(P35:AS35,"f") -> 0 | G35: =COUNTIF(P35:AS35,"ast") -> 0 | H35: =COUNTIF(P35:AS35,"cA") -> 0 | I35: =COUNTIF(P35:AS35,"rtt") -> 0 | J35: =COUNTIF(P35:AS35,"cex") -> 0 | K35: =COUNTIF(P35:AS35,"res") -> 0 | L35: =COUNTIF(P35:AS35,"mA") -> 0 | M35: =COUNTIF(P35:AS35,"at") -> 0 | N35: =COUNTIF(P35:AS35,"TAD") -> 0 | O35: =COUNTIF(P35:AS35,"TP") -> 0
A36: =IFERROR(IF(config!E28="","",config!E28),"") -> JN010461 | B36: =IFERROR(IF(config!F28="","",config!F28),"") -> NOURRI | C36: =IFERROR(IF(config!G28="","",config!G28),"") -> Danny | D36: =COUNTIF(P36:AS36,"p") -> 0 | E36: =COUNTIF(P36:AS36,"PC") -> 0 | F36: =COUNTIF(P36:AS36,"f") -> 0 | G36: =COUNTIF(P36:AS36,"ast") -> 0 | H36: =COUNTIF(P36:AS36,"cA") -> 0 | I36: =COUNTIF(P36:AS36,"rtt") -> 0 | J36: =COUNTIF(P36:AS36,"cex") -> 0 | K36: =COUNTIF(P36:AS36,"res") -> 0 | L36: =COUNTIF(P36:AS36,"mA") -> 0 | M36: =COUNTIF(P36:AS36,"at") -> 0 | N36: =COUNTIF(P36:AS36,"TAD") -> 0 | O36: =COUNTIF(P36:AS36,"TP") -> 0
A37: =IFERROR(IF(config!E29="","",config!E29),"") -> REGIE
A38: =IFERROR(IF(config!E30="","",config!E30),"") -> AGENTS VOIRIE | AV38: VOIRIE
